Workbook

Sheet 음료유형분류
A1: No | B1: 대분류 | C1: 세부유형(식품유형) | D1: 식품공전 정의(주요원재료/함량기준) | E1: 주요 특성 | F1: 대표 제품 예시 | G1: 국내 예상 연매출(억원)
A2: 1 | B2: 과일·채소류음료 | C2: 과·채주스 | D2: 과일 또는 채소를 압착·착즙하거나 이에 식품 또는 식품첨가물을 가한 것. 과즙함량 100%(착즙 또는 농축환원). 직접 착즙(NFC) 또는 농축과즙을 원래 농도로 환원(FC)한 것 | E2: 천연과즙100%, 비타민·미네랄 풍부, 천연산미 | F2: 미닛메이드 오렌지100%, 델몬트 포도100%, 풀무원 아임리얼 | G2: 8500
A3: 2 | B3: 과일·채소류음료 | C3: 과·채음료 | D3: 과일·채소류의 착즙 또는 농축과즙에 식품 또는 식품첨가물을 가한 것으로 과즙함량 10% 이상 100% 미만. 당류·산미료·향료 등 첨가 가능 | E3: 과즙+당류+산미료 혼합, 다양한 맛·가격대 | F3: 써니텐, 캡리썬, 봉봉 | G3: 12000
A4: 3 | B4: 탄산음료류 | C4: 탄산음료 | D4: 먹는물에 식품 또는 식품첨가물과 탄산가스를 혼합한 것. 탄산가스 압력 0.5kg/cm² 이상. 당류·산미료·착색료·향료 등 사용 | E4: CO₂ 2.5~4.0GV, 청량감, 당류 함유 | F4: 코카콜라, 펩시콜라, 칠성사이다, 스프라이트 | G4: 35000
A5: 4 | B5: 탄산음료류 | C5: 탄산수 | D5: 먹는물에 탄산가스만을 혼합한 것 또는 탄산가스를 함유하는 자연수. 탄산가스 압력 0.5kg/cm² 이상. 무당·무칼로리 | E5: CO₂ 2.5~4.0GV, 무설탕, 제로칼로리 | F5: 트레비, 씨그램, 페리에, 초정탄산수 | G5: 5500
A6: 5 | B6: 유산균음료 | C6: 유산균음료(살균) | D6: 유가공품의 유산균 배양액을 살균 처리한 것. 무지유고형분 3% 이상. 살균 후 유산균 사멸 상태. 상온유통 가능 | E6: 유산균 배양액 기반, 상온보관 가능, 산미 | F6: 쿨피스 | G6: 2000
A7: 6 | B7: 유산균음료 | C7: 유산균음료(비살균) | D7: 유가공품의 유산균 배양액을 살균하지 않은 것. 무지유고형분 3% 이상. 유산균수 1ml당 10⁷ 이상(냉장). 냉장유통 필수 | E7: 냉장보관, 유산균 활성, 장건강 기능 | F7: 야쿠르트, 윌, R, 불가리스 | G7: 15000
A8: 7 | B8: 커피음료 | C8: 커피 | D8: 커피원두를 볶은 것 또는 이를 추출한 액에 식품 또는 식품첨가물을 가한 것. 조제커피: 커피고형분 0.5%이상+당류/유제품. 추출커피: 커피고형분 1.0%이상 | E8: 커피고형분 기준 충족, 카페인, 다양한 RTD형태 | F8: 조지아, 레쓰비, 칸타타, 스타벅스 RTD | G8: 22000
A9: 8 | B9: 차음료 | C9: 침출차 | D9: 차나무의 잎을 주원료로 하여 뜨거운 물 등으로 추출한 것. 녹차(불발효), 홍차(완전발효), 우롱차(반발효) 등. 추출물 고형분 기준 적용 | E9: 카테킨, 항산화, 소량 카페인, 전통차류 | F9: 립톤 아이스티, 보성녹차, 오설록 | G9: 3500
A10: 9 | B10: 차음료 | C10: 액상차 | D10: 식물성 원료(곡류·과일·채소·한약재 등)를 추출하여 음용하는 것에 식품 또는 식품첨가물을 가한 것. RTD 형태 | E10: 편의성, 다양한 풍미, 대용량 RTD | F10: 광동 옥수수수염차, 17차, 하늘보리 | G10: 9000
A11: 10 | B11: 차음료 | C11: 고형차 | D11: 식물성 원료를 주원료로 분말·과립 등 고형 형태로 가공한 것. 분말·과립·스틱형 | E11: 분말·스틱형, 용해 편의성, 휴대성 | F11: 맥심 모카믹스 티, 담터 율무차, 녹차분말 | G11: 4000
A12: 11 | B12: 두유류 | C12: 두유 | D12: 대두를 주원료로 하여 가공한 것. 대두고형분 7% 이상(두유), 4% 이상(두유액). 가당/무가당 구분 | E12: 식물성 단백질, 이소플라본, 칼슘 강화 | F12: 베지밀, 삼육두유, 매일두유 | G12: 8000
A13: 12 | B13: 기능성음료 | C13: 에너지음료 | D13: 혼합음료 또는 탄산음료에 카페인·타우린·비타민B군 등 기능성 원료를 강화한 음료. 카페인 총 함량 표시 의무(150mg 이하/개) | E13: 고카페인(≤150mg), 타우린, 에너지 부스트 | F13: 레드불, 몬스터, 핫식스 | G13: 7000
... A19: 18 | B19: 기타음료 | C19: 젤리음료(곤약젤리) | D19: 곤약분말(글루코만난) 또는 젤라틴 등을 사용하여 젤리 형태로 가공한 음료. 곤약 함량 1% 이상, 식이섬유 함유 | E19: 저칼로리, 식이섬유, 포만감, 간식 대용 | F19: 오리히로 곤약젤리, CJ곤약젤리 | G19: 3000

Sheet 시장제품DB
A1: No | B1: 대분류 | C1: 세부유형 | D1: 제품명 | E1: 제조사 | F1: 배합순위1(원재료/배합비%/원산지) | G1: 배합순위2 | H1: 배합순위3 | I1: 배합순위4 | J1: 배합순위5 | K1: 배합순위6 | L1: 배합순위7 | M1: 용량(ml) | N1: 포장용기 | O1: 가격(원) | P1: 비고 | Q1: 당도(Bx) | R1: 산도(%) | S1: pH | T1: 당산비
A2: 1 | B2: 과일·채소류 | C2: 과·채주스 | D2: 미닛메이드 오렌지100% | E2: 코카콜라 | F2: 오렌지농축과즙/20%/브라질 | G2: 정제수/80%/국내 | H2: — | I2: — | J2: — | K2: — | L2: — | M2: 1000 | N2: PET | O2: 3500 | P2: 농축환원
A3: 2 | B3: 과일·채소류 | C3: 과·채주스 | D3: 델몬트 포도100% | E3: 롯데칠성 | F3: 포도농축과즙/18%/칠레 | G3: 정제수/82%/국내 | H3: — | I3: — | J3: — | K3: — | L3: — | M3: 1000 | N3: PET | O3: 3500 | P3: 농축환원
A4: 3 | B4: 과일·채소류 | C4: 과·채주스 | D4: 풀무원 아임리얼 토마토 | E4: 풀무원 | F4: 토마토착즙/100%/국내 | G4: — | H4: — | I4: — | J4: — | K4: — | L4: — | M4: 190 | N4: 유리병 | O4: 2500 | P4: NFC,냉장
A5: 4 | B5: 과일·채소류 | C5: 과·채주스 | D5: 제주감귤 생과즙 | E5: 제주농협 | F5: 감귤착즙/100%/제주 | G5: — | H5: — | I5: — | J5: — | K5: — | L5: — | M5: 200 | N5: 파우치 | O5: 1800 | P5: NFC
A6: 5 | B6: 과일·채소류 | C6: 과·채주스 | D6: 매일 스위트컵 사과 | E6: 매일유업 | F6: 사과농축과즙/22%/국내 | G6: 정제수/78%/국내 | H6: — | I6: — | J6: — | K6: — | L6: — | M6: 200 | N6: 종이팩 | O6: 900
A7: 6 | B7: 과일·채소류 | C7: 과·채주스 | D7: 가야농장 석류100% | E7: 남양유업 | F7: 석류농축과즙/16%/이란 | G7: 정제수/84%/국내 | H7: — | I7: — | J7: — | K7: — | L7: — | M7: 1000 | N7: PET | O7: 4500
A8: 7 | B8: 과일·채소류 | C8: 과·채주스 | D8: 썬키스트 자몽100% | E8: 해태음료 | F8: 자몽농축과즙/20%/미국 | G8: 정제수/80%/국내 | H8: — | I8: — | J8: — | K8: — | L8: — | M8: 1000 | N8: PET | O8: 3800
A9: 8 | B9: 과일·채소류 | C9: 과·채주스 | D9: 델몬트 망고100% | E9: 롯데칠성 | F9: 망고농축과즙/20%/인도 | G9: 정제수/80%/국내 | H9: — | I9: — | J9: — | K9: — | L9: — | M9: 1000 | N9: PET | O9: 3800
A10: 9 | B10: 과일·채소류 | C10: 과·채주스 | D10: 상쾌한하루 야채 | E10: 한국야쿠르트 | F10: 당근농축즙/10%/국내 | G10: 토마토농축즙/8%/국내 | H10: 사과농축즙/5%/국내 | I10: 정제수/75%/국내 | J10: 비타민C/0.02%/중국 | K10: 구연산/0.08%/중국 | L10: 향료/0.9%/국내 | M10: 130 | N10: PET | O10: 1500 | P10: 야채주스
A11: 10 | B11: 과일·채소류 | C11: 과·채주스 | D11: 하루야채 그린 | E11: 한국야쿠르트 | F11: 케일농축즙/8%/국내 | G11: 브로콜리농축즙/6%/국내 | H11: 셀러리농축즙/4%/국내 | I11: 사과농축즙/5%/국내 | J11: 정제수/76%/국내 | K11: 비타민C/0.02%/중국 | L11: 향료/0.98%/국내 | M11: 130 | N11: PET | O11: 1500 | P11: 녹색채소
A12: 11 | B12: 과일·채소류 | C12: 과·채주스 | D12: 바나나는원래하얗다 | E12: 빙그레 | F12: 바나나농축과즙/15%/에콰도르 | G12: 정제수/75%/국내 | H12: 액상과당/8%/국내 | I12: 탈지분유/1.5%/국내 | J12: 향료/0.3%/국내 | K12: 유화제/0.1%/국내 | L12: 비타민C/0.1%/중국 | M12: 240 | N12: PE(HDPE) | O12: 1200 | P12: PE용기
A13: 12 | B13: 과일·채소류 | C13: 과·채주스 | D13: 매경 NFC 제주당근 | E13: 매경HN | F13: 당근착즙/100%/제주 | G13: — | H13: — | I13: — | J13: — | K13: — | L13: — | M13: 190 | N13: 유리병 | O13: 2800 | P13: NFC,냉장
A14: 13 | B14: 과일·채소류 | C14: 과·채음료 | D14: 써니텐 오렌지 | E14: 해태음료 | F14: 정제수/76%/국내 | G14: 액상과당/10%/국내 | H14: 오렌지농축과즙/10%/브라질 | I14: 구연산/0.3%/중국 | J14: 오렌지향/0.2%/국내 | K14: 비타민C/0.1%/중국 | L14: 베타카로틴/0.01%/독일 | M14: 240 | N14: 캔 | O14: 800
A15: 14 | B15: 과일·채소류 | C15: 과·채음료 | D15: 캡리썬 오렌지 | E15: 농심 | F15: 정제수/74%/국내 | G15: 설탕/11%/호주 | H15: 오렌지농축과즙/12%/브라질 | I15: 구연산/0.3%/중국 | J15: 비타민C/0.1%/중국 | K15: 오렌지향/0.15%/독일 | L15: — | M15: 200 | N15: 파우치 | O15: 700 | P15: 어린이용
A16: 15 | B16: 과일·채소류 | C16: 과·채음료 | D16: 봉봉 포도 | E16: 해태음료 | F16: 정제수/72%/국내 | G16: 포도농축과즙/12%/칠레 | H16: 액상과당/9%/국내 | I16: 나타데코코/5%/태국 | J16: 구연산/0.3%/중국 | K16: 포도향/0.2%/국내 | L16: 안토시아닌/0.01%/이탈리아 | M16: 500 | N16: PET | O16: 1800 | P16: 과립함유
A17: 16 | B17: 과일·채소류 | C17: 과·채음료 | D17: 미닛메이드 스파클링포도 | E17: 코카콜라 | F17: 정제수/70%/국내 | G17: 포도농축과즙/10%/칠레 | H17: 액상과당/8%/국내 | I17: 탄산가스/3%/국내 | J17: 구연산/0.3%/중국 | K17: 포도향/0.2%/국내 | L17: — | M17: 350 | N17: 캔 | O17: 1500 | P17: 탄산과즙
A18: 17 | B18: 과일·채소류 | C18: 과·채음료 | D18: 트로피카나 스파클링레몬 | E18: 롯데칠성 | F18: 정제수/78%/국내 | G18: 액상과당/9%/국내 | H18: 레몬농축과즙/5%/아르헨티나 | I18: 탄산가스/3%/국내 | J18: 구연산/0.5%/중국 | K18: 레몬향/0.2%/국내 | L18: 비타민C/0.05%/중국 | M18: 355 | N18: 캔 | O18: 1500
A19: 18 | B19: 과일·채소류 | C19: 과·채음료 | D19: 닥터유 제주감귤 | E19: 오리온 | F19: 정제수/68%/국내 | G19: 감귤과즙/25%/제주 | H19: 액상과당/5%/국내 | I19: 구연산/0.2%/중국 | J19: 비타민C/0.1%/중국 | K19: 감귤향/0.1%/국내 | L19: — | M19: 210 | N19: PET | O19: 1800 | P19: 유기농
A20: 19 | B20: 과일·채소류 | C20: 과·채음료 | D20: 델몬트 콜드 오렌지 | E20: 롯데칠성 | F20: 정제수/45%/국내 | G20: 오렌지농축과즙/50%/브라질 | H20: 구연산/0.2%/중국 | I20: 비타민C/0.05%/중국 | J20: 오렌지향/0.1%/국내 | K20: — | L20: — | M20: 190 | N20: PET | O20: 1500 | P20: 과즙50%
A21: 20 | B21: 과일·채소류 | C21: 과·채음료 | D21: ABC주스 | E21: 풀무원 | F21: 사과착즙/40%/국내 | G21: 비트착즙/30%/국내 | H21: 당근착즙/30%/국내 | I21: — | J21: — | K21: — | L21: — | M21: 200 | N21: 파우치 | O21: 2500 | P21: NFC
A22: 21 | B22: 과일·채소류 | C22: 과·채음료 | D22: 쿨피스 복숭아 | E22: 동아오츠카 | F22: 정제수/82%/국내 | G22: 액상과당/10%/국내 | H22: 복숭아농축과즙/3%/중국 | I22: 탈지분유/2%/뉴질랜드 | J22: 구연산/0.4%/중국 | K22: 복숭아향/0.2%/국내 | L22: 젖산/0.1%/일본 | M22: 345 | N22: PET | O22: 1200
A23: 22 | B23: 과일·채소류 | C23: 과·채음료 | D23: 롯데 델몬트 알로에 | E23: 롯데칠성 | F23: 정제수/73%/국내 | G23: 알로에과육/10%/태국 | H23: 액상과당/9%/국내 | I23: 포도농축과즙/5%/칠레 | J23: 구연산/0.3%/중국 | K23: 알로에향/0.1%/국내 | L23: CMC/0.05%/일본 | M23: 500 | N23: PP(내열) | O23: 1800 | P23: PP용기,과립
A24: 23 | B24: 과일·채소류 | C24: 과·채음료 | D24: 농심 웰치스 포도 | E24: 농심 | F24: 정제수/70%/국내 | G24: 포도농축과즙/15%/칠레 | H24: 액상과당/10%/국내 | I24: 구연산/0.4%/중국 | J24: 포도향/0.2%/국내 | K24: 안토시아닌/0.01%/이탈리아 | L24: 비타민C/0.05%/중국 | M24: 355 | N24: 캔 | O24: 1500
A25: 24 | B25: 과일·채소류 | C25: 과·채음료 | D25: 코코팜 망고 | E25: 해태음료 | F25: 정제수/68%/국내 | G25: 망고농축과즙/12%/인도 | H25: 액상과당/10%/국내 | I25: 나타데코코/6%/태국 | J25: 구연산/0.3%/중국 | K25: 망고향/0.2%/국내 | L25: 베타카로틴/0.01%/독일 | M25: 340 | N25: 캔 | O25: 1500 | P25: 과립함유
A26: 25 | B26: 탄산음료류 | C26: 탄산음료 | D26: 코카콜라 오리지널 | E26: 코카콜라 | F26: 정제수/86%/국내 | G26: 액상과당/10%/국내 | H26: 탄산가스/3%/국내 | I26: 카라멜색소/0.4%/국내 | J26: 인산/0.06%/일본 | K26: 천연향료/0.04%/미국 | L26: 카페인/0.01%/중국 | M26: 355 | N26: 캔 | O26: 1300
A27: 26 | B27: 탄산음료류 | C27: 탄산음료 | D27: 펩시콜라 | E27: 롯데칠성 | F27: 정제수/86%/국내 | G27: 액상과당/10%/국내 | H27: 탄산가스/3%/국내 | I27: 카라멜색소/0.4%/국내 | J27: 인산/0.06%/일본 | K27: 천연향료/0.04%/미국 | L27: 카페인/0.01%/중국 | M27: 355 | N27: 캔 | O27: 1200
A28: 27 | B28: 탄산음료류 | C28: 탄산음료 | D28: 스프라이트 | E28: 코카콜라 | F28: 정제수/86%/국내 | G28: 액상과당/10%/국내 | H28: 탄산가스/3%/국내 | I28: 구연산/0.4%/중국 | J28: 레몬라임향/0.1%/미국 | K28: — | L28: — | M28: 355 | N28: 캔 | O28: 1300 | P28: 레몬라임
A29: 28 | B29: 탄산음료류 | C29: 탄산음료 | D29: 칠성사이다 | E29: 롯데칠성 | F29: 정제수/87%/국내 | G29: 액상과당/9.5%/국내 | H29: 탄산가스/3%/국내 | I29: 구연산/0.35%/중국 | J29: 레몬라임향/0.1%/국내 | K29: — | L29: — | M29: 355 | N29: 캔 | O29: 1200
A30: 29 | B30: 탄산음료류 | C30: 탄산음료 | D30: 코카콜라 제로 | E30: 코카콜라 | F30: 정제수/96%/국내 | G30: 탄산가스/3%/국내 | H30: 카라멜색소/0.4%/국내 | I30: 인산/0.06%/일본 | J30: 아스파탐/0.05%/일본 | K30: 아세설팜K/0.03%/독일 | L30: 천연향료/0.04%/미국 | M30: 355 | N30: 캔 | O30: 1400 | P30: 무설탕
A31: 30 | B31: 탄산음료류 | C31: 탄산음료 | D31: 펩시 제로슈거 | E31: 롯데칠성 | F31: 정제수/96%/국내 | G31: 탄산가스/3%/국내 | H31: 카라멜색소/0.4%/국내 | I31: 인산/0.05%/일본 | J31: 수크랄로스/0.02%/중국 | K31: 아세설팜K/0.03%/독일 | L31: 천연향료/0.04%/미국 | M31: 355 | N31: 캔 | O31: 1300 | P31: 무설탕
A32: 31 | B32: 탄산음료류 | C32: 탄산음료 | D32: 환타 오렌지 | E32: 코카콜라 | F32: 정제수/82%/국내 | G32: 액상과당/10%/국내 | H32: 오렌지농축과즙/3%/브라질 | I32: 탄산가스/3%/국내 | J32: 구연산/0.3%/중국 | K32: 베타카로틴/0.02%/독일 | L32: 오렌지향/0.1%/미국 | M32: 355 | N32: 캔 | O32: 1300
A33: 32 | B33: 탄산음료류 | C33: 탄산음료 | D33: 닥터페퍼 | E33: 코카콜라 | F33: 정제수/86%/국내 | G33: 액상과당/10%/미국 | H33: 탄산가스/3%/미국 | I33: 카라멜색소/0.4%/미국 | J33: 인산/0.06%/미국 | K33: 천연향료/0.1%/미국 | L33: 카페인/0.01%/미국 | M33: 355 | N33: 캔 | O33: 1500 | P33: 수입
A34: 33 | B34: 탄산음료류 | C34: 탄산음료 | D34: 마운틴듀 | E34: 롯데칠성 | F34: 정제수/84%/국내 | G34: 액상과당/10%/국내 | H34: 탄산가스/3%/국내 | I34: 구연산/0.5%/중국 | J34: 오렌지농축과즙/1%/브라질 | K34: 카페인/0.02%/중국 | L34: 황색4호/0.01%/국내 | M34: 355 | N34: 캔 | O34: 1300
A35: 34 | B35: 탄산음료류 | C35: 탄산음료 | D35: 밀키스 | E35: 롯데칠성 | F35: 정제수/78%/국내 | G35: 액상과당/9%/국내 | H35: 탄산가스/3%/국내 | I35: 탈지분유/4%/뉴질랜드 | J35: 유청분말/3%/네덜란드 | K35: 구연산/0.3%/중국 | L35: 밀크향/0.15%/국내 | M35: 250 | N35: 캔 | O35: 1000 | P35: 유성탄산
A36: 35 | B36: 탄산음료류 | C36: 탄산음료 | D36: 이온더핏 스파클링 | E36: CJ제일제당 | F36: 정제수/88%/국내 | G36: 탄산가스/3%/국내 | H36: 이소말트올리고당/5%/국내 | I36: 구연산/0.4%/중국 | J36: 염화나트륨/0.15%/국내 | K36: 비타민C/0.05%/중국 | L36: 레몬향/0.1%/국내 | M36: 350 | N36: PP(내열) | O36: 1500 | P36: PP용기
A37: 36 | B37: 탄산음료류 | C37: 탄산음료 | D37: 웰치스 소다 포도 | E37: 농심 | F37: 정제수/74%/국내 | G37: 포도농축과즙/10%/칠레 | H37: 액상과당/8%/국내 | I37: 탄산가스/3%/국내 | J37: 구연산/0.3%/중국 | K37: 포도향/0.2%/국내 | L37: 안토시아닌/0.01%/이탈리아 | M37: 355 | N37: 캔 | O37: 1500
A38: 37 | B38: 탄산음료류 | C38: 탄산수 | D38: 트레비 레몬 | E38: 롯데칠성 | F38: 정제수/96.5%/국내 | G38: 탄산가스/3%/국내 | H38: 레몬향/0.3%/국내 | I38: 구연산/0.2%/중국 | J38: — | K38: — | L38: — | M38: 500 | N38: PET | O38: 1200 | P38: 플레이버
A39: 38 | B39: 탄산음료류 | C39: 탄산수 | D39: 씨그램 플레인 | E39: 코카콜라 | F39: 정제수/97%/국내 | G39: 탄산가스/3%/국내 | H39: — | I39: — | J39: — | K39: — | L39: — | M39: 450 | N39: PET | O39: 1200 | P39: 플레인
A40: 39 | B40: 탄산음료류 | C40: 탄산수 | D40: 초정탄산수 | E40: 일화 | F40: 천연광천수/97%/국내(청주) | G40: 탄산가스/3%/국내 | H40: — | I40: — | J40: — | K40: — | L40: — | M40: 500 | N40: PET | O40: 1300 | P40: 천연탄산수
...

Sheet 원료DB
A1: No | B1: 원료대분류 | C1: 원료소분류 | D1: 원료명 | E1: Brix(°) | F1: pH | G1: 산도(%) | H1: 감미도(설탕대비) | I1: 주요성분 | J1: 공급형태 | K1: 보관조건 | L1: 예상단가(원/kg) | M1: 1%사용시 Brix기여(°) | N1: 1%사용시 pH영향 | O1: 1%사용시 산도기여(%) | P1: 1%사용시 감미기여 | Q1: 비고
A2: 1 | B2: 과즙농축액 | C2: 감귤류 | D2: 오렌지농축과즙(65Brix) | E2: 65 | F2: 3.5 | G2: 4.5 | H2: 0 | I2: 비타민C, 구연산, 헤스페리딘 | J2: 액상(드럼) | K2: 냉장 0~5℃ | L2: 4500 | M2: 0.65 | N2: ↓3.5방향 | O2: 0.045 | P2: 0 | Q2: 5배농축
A3: 2 | B3: 과즙농축액 | C3: 감귤류 | D3: 자몽농축과즙(55Brix) | E3: 55 | F3: 3 | G3: 5 | H3: 0 | I3: 나린진, 비타민C, 구연산 | J3: 액상(드럼) | K3: 냉장 0~5℃ | L3: 5000 | M3: 0.55 | N3: ↓3.0방향 | O3: 0.05 | P3: 0 | Q3: 5배농축
A4: 3 | B4: 과즙농축액 | C4: 감귤류 | D4: 레몬농축과즙(45Brix) | E4: 45 | F4: 2.2 | G4: 6.5 | H4: 0 | I4: 구연산, 비타민C, 리모넨 | J4: 액상(드럼) | K4: 냉장 0~5℃ | L4: 5500 | M4: 0.45 | N4: ↓2.2방향 | O4: 0.065 | P4: 0 | Q4: 4배농축, 고산
A5: 4 | B5: 과즙농축액 | C5: 감귤류 | D5: 라임농축과즙(45Brix) | E5: 45 | F5: 2 | G5: 7 | H5: 0 | I5: 구연산, 비타민C | J5: 액상(드럼) | K5: 냉장 0~5℃ | L5: 6000 | M5: 0.45 | N5: ↓2.0방향 | O5: 0.07 | P5: 0 | Q5: 4배농축
A6: 5 | B6: 과즙농축액 | C6: 감귤류 | D6: 감귤농축과즙(60Brix) | E6: 60 | F6: 3.5 | G6: 4 | H6: 0 | I6: 비타민C, 헤스페리딘 | J6: 액상(드럼) | K6: 냉장 0~5℃ | L6: 5000 | M6: 0.6 | N6: ↓3.5방향 | O6: 0.04 | P6: 0 | Q6: 4배농축
A7: 6 | B7: 과즙농축액 | C7: 감귤류 | D7: 유자농축과즙(55Brix) | E7: 55 | F7: 2.8 | G7: 5.5 | H7: 0 | I7: 유자향(리모넨), 비타민C | J7: 액상(드럼) | K7: 냉장 0~5℃ | L7: 8000 | M7: 0.55 | N7: ↓2.8방향 | O7: 0.055 | P7: 0 | Q7: 국산
A8: 7 | B8: 과즙농축액 | C8: 감귤류 | D8: 금귤농축과즙(50Brix) | E8: 50 | F8: 3.2 | G8: 4.5 | H8: 0 | I8: 비타민C, 플라보노이드 | J8: 액상(드럼) | K8: 냉장 0~5℃ | L8: 9000 | M8: 0.5 | N8: ↓3.2방향 | O8: 0.045 | P8: 0
A9: 8 | B9: 과즙농축액 | C9: 감귤류 | D9: 탄제린농축과즙(60Brix) | E9: 60 | F9: 3.6 | G9: 3.8 | H9: 0 | I9: 비타민C, 카로티노이드 | J9: 액상(드럼) | K9: 냉장 0~5℃ | L9: 5500 | M9: 0.6 | N9: ↓3.6방향 | O9: 0.038 | P9: 0
A10: 9 | B10: 과즙농축액 | C10: 열대과일 | D10: 망고농축과즙(65Brix) | E10: 65 | F10: 4 | G10: 2 | H10: 0 | I10: 비타민A, 베타카로틴, 당류 | J10: 액상(드럼) | K10: 냉장 0~5℃ | L10: 5500 | M10: 0.65 | N10: ↓4.0방향 | O10: 0.02 | P10: 0 | Q10: 5배농축
A11: 10 | B11: 과즙농축액 | C11: 열대과일 | D11: 파인애플농축과즙(62Brix) | E11: 62 | F11: 3.5 | G11: 3.5 | H11: 0 | I11: 브로멜린, 비타민C, 구연산 | J11: 액상(드럼) | K11: 냉장 0~5℃ | L11: 4000 | M11: 0.62 | N11: ↓3.5방향 | O11: 0.035 | P11: 0 | Q11: 5배농축
A12: 11 | B12: 과즙농축액 | C12: 열대과일 | D12: 패션프루트농축과즙(50Brix) | E12: 50 | F12: 2.8 | G12: 4.5 | H12: 0 | I12: 구연산, 비타민C, 카로티노이드 | J12: 액상(드럼) | K12: 냉장 0~5℃ | L12: 9000 | M12: 0.5 | N12: ↓2.8방향 | O12: 0.045 | P12: 0 | Q12: 고산미
A13: 12 | B13: 과즙농축액 | C13: 열대과일 | D13: 구아바농축과즙(40Brix) | E13: 40 | F13: 4 | G13: 1.5 | H13: 0 | I13: 비타민C, 라이코펜 | J13: 액상(드럼) | K13: 냉장 0~5℃ | L13: 8000 | M13: 0.4 | N13: ↓4.0방향 | O13: 0.015 | P13: 0
A14: 13 | B14: 과즙농축액 | C14: 열대과일 | D14: 리치농축과즙(60Brix) | E14: 60 | F14: 4.5 | G14: 1.8 | H14: 0 | I14: 비타민C, 폴리페놀 | J14: 액상(드럼) | K14: 냉장 0~5℃ | L14: 10000 | M14: 0.6 | N14: ↓4.5방향 | O14: 0.018 | P14: 0
A15: 14 | B15: 과즙농축액 | C15: 열대과일 | D15: 코코넛워터농축액(25Brix) | E15: 25 | F15: 5 | G15: 0.5 | H15: 0 | I15: 칼륨, 마그네슘, 전해질 | J15: 액상(드럼) | K15: 냉장 0~5℃ | L15: 6000 | M15: 0.25 | N15: ↓5.0방향 | O15: 0.005 | P15: 0 | Q15: 2.5배농축
A16: 15 | B16: 과즙농축액 | C16: 열대과일 | D16: 바나나퓨레(22Brix) | E16: 22 | F16: 4.5 | G16: 0.8 | H16: 0 | I16: 칼륨, 비타민B6, 식이섬유 | J16: 퓨레(드럼) | K16: 냉동 -18℃ | L16: 3500 | M16: 0.22 | N16: ↓4.5방향 | O16: 0.008 | P16: 0 | Q16: 퓨레형
A17: 16 | B17: 과즙농축액 | C17: 인과류 | D17: 사과농축과즙(70Brix) | E17: 70 | F17: 3.5 | G17: 3.5 | H17: 0 | I17: 사과산, 비타민C, 폴리페놀 | J17: 액상(드럼) | K17: 냉장 0~5℃ | L17: 3500 | M17: 0.7 | N17: ↓3.5방향 | O17: 0.035 | P17: 0 | Q17: 5배농축
A18: 17 | B18: 과즙농축액 | C18: 인과류 | D18: 배농축과즙(65Brix) | E18: 65 | F18: 4.2 | G18: 2 | H18: 0 | I18: 솔비톨, 사과산, 식이섬유 | J18: 액상(드럼) | K18: 냉장 0~5℃ | L18: 4500 | M18: 0.65 | N18: ↓4.2방향 | O18: 0.02 | P18: 0 | Q18: 5배농축
A19: 18 | B19: 과즙농축액 | C19: 핵과류 | D19: 복숭아농축과즙(65Brix) | E19: 65 | F19: 3.8 | G19: 3 | H19: 0 | I19: 비타민C, 식이섬유, 사과산 | J19: 액상(드럼) | K19: 냉장 0~5℃ | L19: 5000 | M19: 0.65 | N19: ↓3.8방향 | O19: 0.03 | P19: 0 | Q19: 5배농축
A20: 19 | B20: 과즙농축액 | C20: 핵과류 | D20: 체리농축과즙(65Brix) | E20: 65 | F20: 3.4 | G20: 4 | H20: 0 | I20: 안토시아닌, 폴리페놀 | J20: 액상(드럼) | K20: 냉장 0~5℃ | L20: 12000 | M20: 0.65 | N20: ↓3.4방향 | O20: 0.04 | P20: 0
A21: 20 | B21: 과즙농축액 | C21: 핵과류 | D21: 매실농축과즙(60Brix) | E21: 60 | F21: 2.5 | G21: 6 | H21: 0 | I21: 구연산, 사과산, 피크르산 | J21: 액상(드럼) | K21: 냉장 0~5℃ | L21: 7000 | M21: 0.6 | N21: ↓2.5방향 | O21: 0.06 | P21: 0 | Q21: 고산미
A22: 21 | B22: 과즙농축액 | C22: 핵과류 | D22: 살구농축과즙(60Brix) | E22: 60 | F22: 3.6 | G22: 3.2 | H22: 0 | I22: 베타카로틴, 비타민A, 사과산 | J22: 액상(드럼) | K22: 냉장 0~5℃ | L22: 6000 | M22: 0.6 | N22: ↓3.6방향 | O22: 0.032 | P22: 0
A23: 22 | B23: 과즙농축액 | C23: 장과류 | D23: 포도농축과즙(68Brix) | E23: 68 | F23: 3.3 | G23: 5 | H23: 0 | I23: 폴리페놀, 레스베라트롤, 안토시아닌 | J23: 액상(드럼) | K23: 냉장 0~5℃ | L23: 4000 | M23: 0.68 | N23: ↓3.3방향 | O23: 0.05 | P23: 0 | Q23: 5배농축
A24: 23 | B24: 과즙농축액 | C24: 장과류 | D24: 블루베리농축과즙(65Brix) | E24: 65 | F24: 3.2 | G24: 3.5 | H24: 0 | I24: 안토시아닌, 폴리페놀, 비타민C | J24: 액상(드럼) | K24: 냉장 0~5℃ | L24: 15000 | M24: 0.65 | N24: ↓3.2방향 | O24: 0.035 | P24: 0
A25: 24 | B25: 과즙농축액 | C25: 장과류 | D25: 크랜베리농축과즙(50Brix) | E25: 50 | F25: 2.5 | G25: 5.5 | H25: 0 | I25: 프로안토시아니딘, 퀴닌산 | J25: 액상(드럼) | K25: 냉장 0~5℃ | L25: 14000 | M25: 0.5 | N25: ↓2.5방향 | O25: 0.055 | P25: 0 | Q25: 고산미
A26: 25 | B26: 과즙농축액 | C26: 장과류 | D26: 라즈베리농축과즙(55Brix) | E26: 55 | F26: 3 | G26: 4.5 | H26: 0 | I26: 안토시아닌, 엘라그산 | J26: 액상(드럼) | K26: 냉장 0~5℃ | L26: 16000 | M26: 0.55 | N26: ↓3.0방향 | O26: 0.045 | P26: 0
A27: 26 | B27: 과즙농축액 | C27: 장과류 | D27: 딸기농축과즙(55Brix) | E27: 55 | F27: 3.3 | G27: 3.5 | H27: 0 | I27: 비타민C, 안토시아닌, 엘라그산 | J27: 액상(드럼) | K27: 냉장 0~5℃ | L27: 12000 | M27: 0.55 | N27: ↓3.3방향 | O27: 0.035 | P27: 0
A28: 27 | B28: 과즙농축액 | C28: 장과류 | D28: 석류농축과즙(65Brix) | E28: 65 | F28: 3 | G28: 4.5 | H28: 0 | I28: 엘라그산, 푸니칼라긴, 안토시아닌 | J28: 액상(드럼) | K28: 냉장 0~5℃ | L28: 11000 | M28: 0.65 | N28: ↓3.0방향 | O28: 0.045 | P28: 0
A29: 28 | B29: 과즙농축액 | C29: 장과류 | D29: 아사이베리농축과즙(14Brix) | E29: 14 | F29: 3.5 | G29: 2 | H29: 0 | I29: 안토시아닌, 오메가지방산 | J29: 퓨레(드럼) | K29: 냉동 -18℃ | L29: 25000 | M29: 0.14 | N29: ↓3.5방향 | O29: 0.02 | P29: 0 | Q29: 냉동퓨레
A30: 29 | B30: 과즙농축액 | C30: 채소류 | D30: 토마토농축과즙(28Brix) | E30: 28 | F30: 4.2 | G30: 2.5 | H30: 0 | I30: 라이코펜, 비타민C, 칼륨 | J30: 페이스트(드럼) | K30: 냉장 0~5℃ | L30: 3000 | M30: 0.28 | N30: ↓4.2방향 | O30: 0.025 | P30: 0 | Q30: 3배농축
A31: 30 | B31: 과즙농축액 | C31: 채소류 | D31: 당근농축과즙(40Brix) | E31: 40 | F31: 6 | G31: 0.3 | H31: 0 | I31: 베타카로틴, 비타민A | J31: 액상(드럼) | K31: 냉장 0~5℃ | L31: 4000 | M31: 0.4 | N31: ↓6.0방향 | O31: 0.003 | P31: 0
A32: 31 | B32: 과즙농축액 | C32: 채소류 | D32: 비트농축과즙(45Brix) | E32: 45 | F32: 5.5 | G32: 0.5 | H32: 0 | I32: 베타인, 질산염, 철분 | J32: 액상(드럼) | K32: 냉장 0~5℃ | L32: 5000 | M32: 0.45 | N32: ↓5.5방향 | O32: 0.005 | P32: 0 | Q32: 천연색소겸용
A33: 32 | B33: 과즙농축액 | C33: 채소류 | D33: 셀러리농축과즙(8Brix) | E33: 8 | F33: 5.8 | G33: 0.2 | H33: 0 | I33: 아피게닌, 칼륨, 식이섬유 | J33: 액상(드럼) | K33: 냉장 0~5℃ | L33: 6000 | M33: 0.08 | N33: ↓5.8방향 | O33: 0.002 | P33: 0
A34: 33 | B34: 과즙농축액 | C34: 채소류 | D34: 케일농축과즙(10Brix) | E34: 10 | F34: 6 | G34: 0.2 | H34: 0 | I34: 비타민K, 루테인, 칼슘 | J34: 액상(드럼) | K34: 냉장 0~5℃ | L34: 7000 | M34: 0.1 | N34: ↓6.0방향 | O34: 0.002 | P34: 0 | Q34: 녹즙용
A35: 34 | B35: 당류 | C35: 일반당류 | D35: 백설탕(정제당) | E35: 99.9 | F35: — | G35: — | H35: 1 | I35: 수크로스 99.9% | J35: 분말(25kg포대) | K35: 상온 | L35: 1200 | M35: 0.999 | N35: 영향없음 | O35: 0 | P35: 0.01 | Q35: 정제당
A36: 35 | B36: 당류 | C36: 일반당류 | D36: 황설탕 | E36: 99 | F36: — | G36: — | H36: — | I36: 수크로스+미량 미네랄 | J36: 분말(25kg포대) | K36: 상온 | L36: 1400 | M36: 0.99 | N36: 영향없음 | O36: 0 | P36: — | Q36: 미정제
A37: 36 | B37: 당류 | C37: 일반당류 | D37: 액상과당(HFCS55) | E37: 77 | F37: 4 | G37: — | H37: 1 | I37: 과당55%, 포도당42% | J37: 액상(드럼) | K37: 상온 | L37: 1000 | M37: 0.77 | N37: 미미(4.0) | O37: 0 | P37: 0.01 | Q37: 고과당
A38: 37 | B38: 당류 | C38: 일반당류 | D38: 액상과당(HFCS42) | E38: 71 | F38: 4 | G38: — | H38: 1 | I38: 과당42%, 포도당53% | J38: 액상(드럼) | K38: 상온 | L38: 900 | M38: 0.71 | N38: 미미(4.0) | O38: 0 | P38: 0.01 | Q38: 저과당
A39: 38 | B39: 당류 | C39: 일반당류 | D39: 물엿(DE42) | E39: 75 | F39: 5 | G39: — | H39: 0.4 | I39: 맥아당, 덱스트린, 포도당 | J39: 액상(드럼) | K39: 상온 | L39: 1100 | M39: 0.75 | N39: 미미(5.0) | O39: 0 | P39: 0.004 | Q39: 전분당
A40: 39 | B40: 당류 | C40: 일반당류 | D40: 포도당(결정) | E40: 99.5 | F40: — | G40: — | H40: — | I40: D-포도당 99.5% | J40: 분말(25kg포대) | K40: 상온 | L40: 1500 | M40: 0.995 | N40: 영향없음 | O40: 0 | P40: —
...

Sheet 음료규격기준
A1: No | B1: 음료유형 | C1: 당도(Brix,°) | D1: pH 범위 | E1: 산도(%) | F1: 과즙함량(%) | G1: 고형분(%) | H1: 탄산가스(GV) | I1: 비고 | J1: Brix_min | K1: Brix_max | L1: pH_min | M1: pH_max | N1: 산도_min | O1: 산도_max
A2: 1 | B2: 과·채주스(100%) | C2: 10~14 | D2: 3.0~4.0 | E2: 0.3~1.5 | F2: ≥100% | G2: ≥10% | H2: — | I2: 과즙함량 100% 이상 | J2: 10 | K2: 14 | L2: 3 | M2: 4 | N2: 0.3 | O2: 1.5
A3: 2 | B3: 과·채음료 | C3: 8~13 | D3: 3.0~4.5 | E3: 0.2~1.0 | F3: 10~99% | G3: ≥5% | H3: — | I3: 과즙 10% 이상 | J3: 8 | K3: 13 | L3: 3 | M3: 4.5 | N3: 0.2 | O3: 1
A4: 3 | B4: 탄산음료 | C4: 10~12 | D4: 2.5~4.0 | E4: 0.1~0.5 | F4: — | G4: — | H4: 2.5~4.0 | J4: 10 | K4: 12 | L4: 2.5 | M4: 4 | N4: 0.1 | O4: 0.5
A5: 4 | B5: 탄산수 | C5: 0 | D5: 4.0~6.5 | E5: 0 | F5: — | G5: — | H5: 2.5~4.0 | I5: 무당, 무칼로리 | J5: 0 | K5: 0 | L5: 4 | M5: 6.5 | N5: 0 | O5: 0
A6: 5 | B6: 커피음료(가당) | C6: 8~11 | D6: 5.5~6.5 | E6: — | F6: — | G6: — | H6: — | I6: 커피고형분 0.5% 이상 | J6: 8 | K6: 11 | L6: 5.5 | M6: 6.5
A7: 6 | B7: 커피음료(블랙) | C7: 0~2 | D7: 4.5~5.5 | E7: — | F7: — | G7: — | H7: — | I7: 커피고형분 1.0% 이상 | J7: 0 | K7: 2 | L7: 4.5 | M7: 5.5
A8: 7 | B8: 침출차/액상차 | C8: 0~8 | D8: 4.0~7.0 | E8: — | F8: — | G8: — | H8: — | I8: 차 추출물 함유 | J8: 0 | K8: 8 | L8: 4 | M8: 7
A9: 8 | B9: 두유 | C9: 8~12 | D9: 6.5~7.0 | E9: — | F9: — | G9: — | H9: — | I9: 대두고형분 7% 이상 | J9: 8 | K9: 12 | L9: 6.5 | M9: 7
A10: 9 | B10: 유산균음료(비살균) | C10: 10~16 | D10: 3.5~4.5 | E10: 0.5~1.5 | F10: — | G10: ≥3% | H10: — | I10: 유산균수 10⁷/ml 이상(냉장) | J10: 10 | K10: 16 | L10: 3.5 | M10: 4.5 | N10: 0.5 | O10: 1.5
A11: 10 | B11: 유산균음료(살균) | C11: 10~14 | D11: 3.5~4.5 | E11: 0.5~1.0 | F11: — | G11: ≥3% | H11: — | I11: 살균처리 | J11: 10 | K11: 14 | L11: 3.5 | M11: 4.5 | N11: 0.5 | O11: 1
A12: 11 | B12: 에너지음료 | C12: 10~14 | D12: 3.0~4.0 | E12: 0.2~0.5 | F12: — | G12: — | H12: — | I12: 카페인 ≤150mg/개 | J12: 10 | K12: 14 | L12: 3 | M12: 4 | N12: 0.2 | O12: 0.5
A13: 12 | B13: 이온음료 | C13: 5~8 | D13: 3.0~4.0 | E13: 0.1~0.3 | F13: — | G13: — | H13: — | I13: 삼투압 200~340 mOsm | J13: 5 | K13: 8 | L13: 3 | M13: 4 | N13: 0.1 | O13: 0.3
A14: 13 | B14: 비타민음료 | C14: 5~10 | D14: 3.0~4.5 | E14: 0.1~0.5 | F14: — | G14: — | H14: — | I14: 비타민C 기능성 표시 기준 | J14: 5 | K14: 10 | L14: 3 | M14: 4.5 | N14: 0.1 | O14: 0.5
A15: 14 | B15: 혼합음료 | C15: 8~13 | D15: 3.0~5.0 | E15: 0.1~0.8 | F15: — | G15: — | H15: 0~3.0 | I15: 2종 이상 혼합 | J15: 8 | K15: 13 | L15: 3 | M15: 5 | N15: 0.1 | O15: 0.8
A16: 15 | B16: 홍삼음료 | C16: 8~14 | D16: 4.0~6.0 | E16: — | F16: — | G16: — | H16: — | I16: 진세노사이드 기준 | J16: 8 | K16: 14 | L16: 4 | M16: 6
A17: 16 | B17: 식혜 | C17: 12~16 | D17: 4.5~6.0 | E17: — | F17: — | G17: — | H17: — | I17: 엿기름 추출 | J17: 12 | K17: 16 | L17: 4.5 | M17: 6
A18: 17 | B18: 젤리음료 | C18: 10~15 | D18: 3.5~4.5 | E18: 0.2~0.5 | F18: — | G18: — | H18: — | I18: 곤약 1% 이상 | J18: 10 | K18: 15 | L18: 3.5 | M18: 4.5 | N18: 0.2 | O18: 0.5

Sheet 표준제조공정_HACCP
A1: No | B1: 음료유형 | C1: 공정단계 | D1: 세부공정 | E1: 작업방법(구체적) | F1: 주요조건/파라미터 | G1: 품질관리포인트 | H1: HACCP 위해요소 | I1: CCP여부 | J1: 한계기준(CL) | K1: 모니터링방법 | L1: 개선조치
A2: 1 | B2: 과·채주스 | C2: 1.원료입고 | D2: 원료입고검사 | E2: 납품된 과즙농축액의 성적서 확인, Brix/pH/산도/색도 자체 측정, 관능검사(맛/향/색) 실시, 이물검사 | F2: Brix 65±2°, pH 규격 내, 이물 없음 | G2: 성적서 vs 자체측정 교차검증, LOT번호 기록 | H2: 생물학적: 잔류농약, 미생물 화학적: 중금속, 잔류SO₂ | I2: N | J2: — | K2: 매입고시 성적서 확인 및 자체 Brix/pH 측정 | L2: 부적합 시 반품, 해당 LOT 격리
A3: 2 | B3: 과·채주스 | C3: 1.원료입고 | D3: 정제수 검사 | E3: 정제수 TDS, pH, 잔류염소, 미생물 검사. RO/UV 처리수 사용 | F3: TDS<100ppm, pH 6.5~7.5, 잔류Cl₂<0.1ppm | G3: 매일 1회 수질검사 | H3: 생물학적: 대장균군 화학적: 잔류염소 | I3: N | J3: — | K3: 매일 수질검사 기록 | L3: 정수설비 점검, 재처리
A4: 3 | B4: 과·채주스 | C4: 2.계량/칭량 | D4: 원료 계량 | E4: 배합표에 따라 각 원료를 전자저울로 정밀 계량. 농축과즙→정제수→당류→산미료→향료 순서로 계량실에서 계량 | F4: 배합표 기준 ±0.5% 이내 | G4: 이중확인(2인 칭량/확인), 계량기록부 작성 | H4: 물리적: 이물혼입 | I4: N | J4: — | K4: 매 배치 계량기록 확인 | L4: 재칭량, 이물제거
A5: 4 | B5: 과·채주스 | C5: 3.배합(조합) | D5: 1차 배합-당/과즙 용해 | E5: 배합탱크에 정제수 투입(총량의 60~70%) → 교반기 가동(100~200rpm) → 농축과즙 투입 → 당류(설탕/액상과당) 투입 → 10분간 균일 교반 | F5: 탱크 온도 20~30℃, 교반속도 150rpm | G5: 과즙 용해 상태 확인, 거품 최소화 | H5: 물리적: 불균일 혼합 | I5: N | J5: — | K5: 배합 중 온도/교반속도 기록 | L5: 추가 교반, 온도 조정
A6: 5 | B6: 과·채주스 | C6: 3.배합(조합) | D6: 2차 배합-산미/향료 | E6: 1차 배합 후 산미료(구연산 등) 투입 → 5분 교반 → 향료 투입 → 잔량 정제수로 볼륨업 → 최종 교반 10분 | F6: 구연산: 배합표 기준량 투입 후 pH 확인 | G6: 산미료 투입 후 pH 즉시 측정 | H6: 화학적: 과다/과소 투입 | I6: N | J6: — | K6: 투입량 더블체크 | L6: 재조정(산미료 추가/희석)
A7: 6 | B7: 과·채주스 | C7: 4.Brix/pH 조정 | D7: 규격 미세조정 | E7: Brix: 당도계(굴절계)로 측정 → 고Brix시 정제수 추가, 저Brix시 당류 추가. pH: pH미터 교정 후 측정 → 고pH시 구연산 추가, 저pH시 구연산Na 추가 | F7: 목표 Brix ±0.2°, pH ±0.1 | G7: 조정 후 3회 재측정하여 평균값 확인 | H7: 화학적: 규격 이탈 | I7: N | J7: — | K7: 조정 전/후 Brix, pH 기록 | L7: 재조정 반복, 최대 3회까지
A8: 7 | B8: 과·채주스 | C8: 5.여과 | D8: 필터 여과 | E8: 50μm → 10μm → 5μm 단계별 필터 통과. 카트리지필터 또는 플레이트필터 사용. 필터 전후 압력차 모니터링 | F8: 차압 <2bar, 유량 규격 내 | G8: 필터 교체주기 관리, 여과 전후 샘플 채취 | H8: 물리적: 이물질 잔류 | I8: N | J8: — | K8: 필터 차압 연속 모니터링 | L8: 필터 교체, 재여과
A9: 8 | B9: 과·채주스 | C9: 6.균질화 | D9: 고압균질 | E9: 균질기에 배합액 통과. 1단 균질(150bar) + 2단 균질(50bar). 과즙 입자를 1μm 이하로 미세화 | F9: 1단 150~200bar, 2단 40~50bar, 온도 60~65℃ | G9: 균질 전후 입도분석(레이저 입도계), 분리 여부 확인 | H9: 물리적: 불완전 균질 | I9: N | J9: — | K9: 균질기 압력/온도 연속기록 | L9: 압력 재조정, 재균질
A10: 9 | B10: 과·채주스 | C10: 7.살균 | D10: UHT 살균(튜블러/플레이트) | E10: 플레이트열교환기 또는 튜블러열교환기에서 급속가열 → 홀딩 → 급속냉각. 살균온도 도달 확인센서 자동기록 | F10: UHT: 135~140℃, 2~4초 홀딩 HTST: 72~75℃, 15~30초 | G10: 온도기록계 연속모니터링, 살균온도 미달시 자동우회(Divert) | H10: ★ 생물학적: 병원성 미생물(대장균O157, 살모넬라, 리스테리아) | I10: CCP-1 | J10: 살균온도 ≥135℃, 홀딩시간 ≥2초 (또는 F₀값 기준) | K10: 온도기록계+자동우회밸브 연속모니터링, 매배치 기록확인 | L10: 자동우회→재살균, 해당배치 격리/폐기, 원인분석 후 설비점검
A11: 10 | B11: 과·채주스 | C11: 8.냉각 | D11: 급속냉각 | E11: 살균 직후 냉각섹션 통과하여 5~10℃로 급속 냉각. 글리콜 또는 냉수 사용 | F11: 냉각 출구 온도 ≤10℃ | G11: 냉각수 온도, 출구 온도 기록 | H11: 생물학적: 미생물 재오염(냉각지연시) | I11: N | J11: — | K11: 냉각 출구온도 연속기록 | L11: 냉각수 온도 조절, 유속 조정
A12: 11 | B12: 과·채주스 | C12: 9.충전/포장 | D12: 무균충전(Aseptic) 또는 Hot-fill | E12: [무균충전] 살균된 제품을 무균환경(Class100)에서 사전 살균된 용기에 충전→밀봉 [Hot-fill] 85℃이상 제품을 용기에 충전→밀봉→반전(캡살균)→냉각 | F12: 무균충전: 충전실 양압유지, HEPA필터 Hot-fill: 충전온도 ≥85℃ | G12: ★ 충전량 오차 ±2%, 밀봉상태(토크, 리크테스트), 충전실 낙하균 검사 | H12: ★ 생물학적: 충전 중 재오염 물리적: 이물혼입, 밀봉불량 | I12: CCP-2 | J12: 무균충전: 충전실 양압 ≥5Pa, 낙하균 ≤1CFU/plate Hot-fill: 충전온도 ≥85℃, 밀봉토크 규격 내 | K12: 매 충전시 온도기록, 시간당 밀봉검사, 매일 낙하균 검사 | L12: 라인 정지→살균→재가동, 불량제품 격리/폐기
A13: 12 | B13: 과·채주스 | C13: 10.냉각/건조 | D13: 충전 후 냉각 | E13: Hot-fill 제품: 반전 후 터널쿨러에서 40℃이하로 냉각. 무균충전: 필요시 냉장보관 | F13: 냉각 후 제품 온도 ≤40℃ | G13: 냉각 프로파일 기록 | H13: 물리적: 용기변형(급냉시) | I13: N | J13: — | K13: 터널쿨러 출구 온도 기록 | L13: 냉각속도 조정
... A49: 48 | B49: 젤리음료 | C49: 6.검사/출하 | D49: 완제품 검사 | E49: 겔강도/Brix/pH/미생물/이물(금속검출기) 검사 | F49: 겔강도 규격, 세균수 기준 | G49: ★ 금속검출기 100% | H49: ★ 물리적: 금속이물 | I49: CCP-3 | J49: Fe≥1.5mm, SUS≥2.5mm | K49: 100% 금속검출기 | L49: 격리, 전후 재검사

Sheet 배합시뮬레이터
A1: 음료 배합비 시뮬레이터 (Formulation Simulator)
A2: ▶ 음료유형+맛 선택 → 가이드배합비 참조 → 배합비 입력(100%기준) → 규격판정 자동확인
A3: 날짜 | B3: 2026. . . | C3: 제품명 | D3: 사과과채음료_시제1호 | I3: 목표용량(ml) | J3: 1000
A4: 음료유형 | B4: 과·채음료 | C4: 맛(Flavor) | D4: 사과 | E4: 직접입력▶ | G4: 규격▶ | H4: =IFERROR("Bx:"&VLOOKUP($B$4,음료규격기준!$B:$I,2,FALSE()),"") -> Bx:8~13 | I4: =IFERROR("pH:"&VLOOKUP($B$4,음료규격기준!$B:$I,3,FALSE()),"") -> pH:3.0~4.5 | J4: =IFERROR("산도:"&VLOOKUP($B$4,음료규격기준!$B:$I,4,FALSE()),"") -> 산도:0.2~1.0 | K4: =IFERROR("과즙:"&VLOOKUP($B$4,음료규격기준!$B:$I,5,FALSE()),"") -> 과즙:10~99% | N4: 품질목표 | O4: 당도(Bx) | P4: 산도(%) | Q4: 감미도 | R4: 단가(원/kg)
E5: 직접입력(F4) 우선적용 | 🟢초록=가이드DB 매칭됨 | 🟡노랑=직접입력(미매칭) | O5: 11 | P5: 0.35 | Q5: — | R5: 1500
A6: No | B6: 구분 | C6: 원료명 (드롭다운) | D6: 배합비 (%) | E6: AI추천 원료명 | F6: AI (%) | G6: 실제사례 원료명 | H6: 사례 (%) | I6: 당도 (Bx) | J6: 산도 (%) | K6: 감미도 | L6: 기능1 | M6: 기능2 | N6: 단가 (원/kg) | O6: 당기여 | P6: 산기여 | Q6: 감미기여 | R6: 단가기여 (원/kg) | S6: 배합량 (g/kg)
A7: 1 | B7: 원재료 | C7: 사과농축과즙(70Brix) | D7: 8 | E7: =IFERROR(VLOOKUP($B$4&"_"&IF($F$4<>"",$F$4,$D$4)&"_1",가이드배합비DB!$A:$G,4,FALSE()),"") -> 사과농축과즙(70Brix) | F7: =IFERROR(VLOOKUP($B$4&"_"&IF($F$4<>"",$F$4,$D$4)&"_1",가이드배합비DB!$A:$G,5,FALSE()),"") -> 8 | G7: =IFERROR(VLOOKUP($B$4&"_"&IF($F$4<>"",$F$4,$D$4)&"_1",가이드배합비DB!$A:$G,6,FALSE()),"") -> 사과농축과즙(70Brix) | H7: =IFERROR(VLOOKUP($B$4&"_"&IF($F$4<>"",$F$4,$D$4)&"_1",가이드배합비DB!$A:$G,7,FALSE()),"") -> 3 | I7: =IFERROR(VLOOKUP(C7,원료DB!$D:$Q,2,FALSE()),"") -> 70 | J7: =IFERROR(VLOOKUP(C7,원료DB!$D:$Q,4,FALSE()),"") -> 3.5 | K7: =IFERROR(VLOOKUP(C7,원료DB!$D:$Q,5,FALSE()),"") -> 0 | N7: =IFERROR(VLOOKUP(C7,원료DB!$D:$Q,9,FALSE()),"") -> 3500 | O7: =IFERROR(D7/100*I7,0) -> 5.6 | P7: =IFERROR(D7/100*J7,0) -> 0.28 | Q7: =IFERROR(D7/100*K7,0) -> 0 | R7: =IFERROR(D7/100*N7,0) -> 280 | S7: =IFERROR(D7*10,0) -> 80
A8: 2 | C8: 사과페이스트 | D8: 5 | E8: =IFERROR(VLOOKUP($B$4&"_"&IF($F$4<>"",$F$4,$D$4)&"_2",가이드배합비DB!$A:$G,4,FALSE()),"") -> 사과페이스트 | F8: =IFERROR(VLOOKUP($B$4&"_"&IF($F$4<>"",$F$4,$D$4)&"_2",가이드배합비DB!$A:$G,5,FALSE()),"") -> 5 | G8: =IFERROR(VLOOKUP($B$4&"_"&IF($F$4<>"",$F$4,$D$4)&"_2",가이드배합비DB!$A:$G,6,FALSE()),"") -> 사과퓨레 | H8: =IFERROR(VLOOKUP($B$4&"_"&IF($F$4<>"",$F$4,$D$4)&"_2",가이드배합비DB!$A:$G,7,FALSE()),"") -> 10 | I8: =IFERROR(VLOOKUP(C8,원료DB!$D:$Q,2,FALSE()),"") -> 4 | J8: =IFERROR(VLOOKUP(C8,원료DB!$D:$Q,4,FALSE()),"") -> 0.25 | K8: =IFERROR(VLOOKUP(C8,원료DB!$D:$Q,5,FALSE()),"") -> 0 | N8: =IFERROR(VLOOKUP(C8,원료DB!$D:$Q,9,FALSE()),"") -> 650 | O8: =IFERROR(D8/100*I8,0) -> 0.2 | P8: =IFERROR(D8/100*J8,0) -> 0.0125 | Q8: =IFERROR(D8/100*K8,0) -> 0 | R8: =IFERROR(D8/100*N8,0) -> 32.5 | S8: =IFERROR(D8*10,0) -> 50
A9: 3 | E9: =IFERROR(VLOOKUP($B$4&"_"&IF($F$4<>"",$F$4,$D$4)&"_3",가이드배합비DB!$A:$G,4,FALSE()),"") -> 0 | F9: =IFERROR(VLOOKUP($B$4&"_"&IF($F$4<>"",$F$4,$D$4)&"_3",가이드배합비DB!$A:$G,5,FALSE()),"") -> 0 | G9: =IFERROR(VLOOKUP($B$4&"_"&IF($F$4<>"",$F$4,$D$4)&"_3",가이드배합비DB!$A:$G,6,FALSE()),"") -> 사과농축과즙(70Brix) | H9: =IFERROR(VLOOKUP($B$4&"_"&IF($F$4<>"",$F$4,$D$4)&"_3",가이드배합비DB!$A:$G,7,FALSE()),"") -> 3 | I9: =IFERROR(VLOOKUP(C9,원료DB!$D:$Q,2,FALSE()),"") | J9: =IFERROR(VLOOKUP(C9,원료DB!$D:$Q,4,FALSE()),"") | K9: =IFERROR(VLOOKUP(C9,원료DB!$D:$Q,5,FALSE()),"") | N9: =IFERROR(VLOOKUP(C9,원료DB!$D:$Q,9,FALSE()),"") | O9: =IFERROR(D9/100*I9,0) -> 0 | P9: =IFERROR(D9/100*J9,0) -> 0 | Q9: =IFERROR(D9/100*K9,0) -> 0 | R9: =IFERROR(D9/100*N9,0) -> 0 | S9: =IFERROR(D9*10,0) -> 0
A10: 4 | E10: =IFERROR(VLOOKUP($B$4&"_"&IF($F$4<>"",$F$4,$D$4)&"_4",가이드배합비DB!$A:$G,4,FALSE()),"") -> 0 | F10: =IFERROR(VLOOKUP($B$4&"_"&IF($F$4<>"",$F$4,$D$4)&"_4",가이드배합비DB!$A:$G,5,FALSE()),"") -> 0 | G10: =IFERROR(VLOOKUP($B$4&"_"&IF($F$4<>"",$F$4,$D$4)&"_4",가이드배합비DB!$A:$G,6,FALSE()),"") -> 0 | H10: =IFERROR(VLOOKUP($B$4&"_"&IF($F$4<>"",$F$4,$D$4)&"_4",가이드배합비DB!$A:$G,7,FALSE()),"") -> 0 | I10: =IFERROR(VLOOKUP(C10,원료DB!$D:$Q,2,FALSE()),"") | J10: =IFERROR(VLOOKUP(C10,원료DB!$D:$Q,4,FALSE()),"") | K10: =IFERROR(VLOOKUP(C10,원료DB!$D:$Q,5,FALSE()),"") | N10: =IFERROR(VLOOKUP(C10,원료DB!$D:$Q,9,FALSE()),"") | O10: =IFERROR(D10/100*I10,0) -> 0 | P10: =IFERROR(D10/100*J10,0) -> 0 | Q10: =IFERROR(D10/100*K10,0) -> 0 | R10: =IFERROR(D10/100*N10,0) -> 0 | S10: =IFERROR(D10*10,0) -> 0
A11: 5 | B11: 당류/ 감미료 | C11: 액상과당(HFCS55) | D11: 7 | E11: =IFERROR(VLOOKUP($B$4&"_"&IF($F$4<>"",$F$4,$D$4)&"_5",가이드배합비DB!$A:$G,4,FALSE()),"") -> 액상과당(HFCS55) | F11: =IFERROR(VLOOKUP($B$4&"_"&IF($F$4<>"",$F$4,$D$4)&"_5",가이드배합비DB!$A:$G,5,FALSE()),"") -> 7 | G11: =IFERROR(VLOOKUP($B$4&"_"&IF($F$4<>"",$F$4,$D$4)&"_5",가이드배합비DB!$A:$G,6,FALSE()),"") -> 프락토올리고당(FOS) | H11: =IFERROR(VLOOKUP($B$4&"_"&IF($F$4<>"",$F$4,$D$4)&"_5",가이드배합비DB!$A:$G,7,FALSE()),"") -> 8.5 | I11: =IFERROR(VLOOKUP(C11,원료DB!$D:$Q,2,FALSE()),"") -> 77 | J11: =IFERROR(VLOOKUP(C11,원료DB!$D:$Q,4,FALSE()),"") -> — | K11: =IFERROR(VLOOKUP(C11,원료DB!$D:$Q,5,FALSE()),"") -> 1 | N11: =IFERROR(VLOOKUP(C11,원료DB!$D:$Q,9,FALSE()),"") -> 1000 | O11: =IFERROR(D11/100*I11,0) -> 5.39 | P11: =IFERROR(D11/100*J11,0) -> 0 | Q11: =IFERROR(D11/100*K11,0) -> 0.07 | R11: =IFERROR(D11/100*N11,0) -> 70 | S11: =IFERROR(D11*10,0) -> 70
A12: 6 | C12: 백설탕(정제당) | D12: 2 | E12: =IFERROR(VLOOKUP($B$4&"_"&IF($F$4<>"",$F$4,$D$4)&"_6",가이드배합비DB!$A:$G,4,FALSE()),"") -> 백설탕(정제당) | F12: =IFERROR(VLOOKUP($B$4&"_"&IF($F$4<>"",$F$4,$D$4)&"_6",가이드배합비DB!$A:$G,5,FALSE()),"") -> 2 | G12: =IFERROR(VLOOKUP($B$4&"_"&IF($F$4<>"",$F$4,$D$4)&"_6",가이드배합비DB!$A:$G,6,FALSE()),"") -> 0 | H12: =IFERROR(VLOOKUP($B$4&"_"&IF($F$4<>"",$F$4,$D$4)&"_6",가이드배합비DB!$A:$G,7,FALSE()),"") -> 0 | I12: =IFERROR(VLOOKUP(C12,원료DB!$D:$Q,2,FALSE()),"") -> 99.9 | J12: =IFERROR(VLOOKUP(C12,원료DB!$D:$Q,4,FALSE()),"") -> — | K12: =IFERROR(VLOOKUP(C12,원료DB!$D:$Q,5,FALSE()),"") -> 1 | N12: =IFERROR(VLOOKUP(C12,원료DB!$D:$Q,9,FALSE()),"") -> 1200 | O12: =IFERROR(D12/100*I12,0) -> 1.998 | P12: =IFERROR(D12/100*J12,0) -> 0 | Q12: =IFERROR(D12/100*K12,0) -> 0.02 | R12: =IFERROR(D12/100*N12,0) -> 24 | S12: =IFERROR(D12*10,0) -> 20
A13: 7 | E13: =IFERROR(VLOOKUP($B$4&"_"&IF($F$4<>"",$F$4,$D$4)&"_7",가이드배합비DB!$A:$G,4,FALSE()),"") -> 0 | F13: =IFERROR(VLOOKUP($B$4&"_"&IF($F$4<>"",$F$4,$D$4)&"_7",가이드배합비DB!$A:$G,5,FALSE()),"") -> 0 | G13: =IFERROR(VLOOKUP($B$4&"_"&IF($F$4<>"",$F$4,$D$4)&"_7",가이드배합비DB!$A:$G,6,FALSE()),"") -> 0 | H13: =IFERROR(VLOOKUP($B$4&"_"&IF($F$4<>"",$F$4,$D$4)&"_7",가이드배합비DB!$A:$G,7,FALSE()),"") -> 0 | I13: =IFERROR(VLOOKUP(C13,원료DB!$D:$Q,2,FALSE()),"") | J13: =IFERROR(VLOOKUP(C13,원료DB!$D:$Q,4,FALSE()),"") | K13: =IFERROR(VLOOKUP(C13,원료DB!$D:$Q,5,FALSE()),"") | N13: =IFERROR(VLOOKUP(C13,원료DB!$D:$Q,9,FALSE()),"") | O13: =IFERROR(D13/100*I13,0) -> 0 | P13: =IFERROR(D13/100*J13,0) -> 0 | Q13: =IFERROR(D13/100*K13,0) -> 0 | R13: =IFERROR(D13/100*N13,0) -> 0 | S13: =IFERROR(D13*10,0) -> 0
A14: 8 | E14: =IFERROR(VLOOKUP($B$4&"_"&IF($F$4<>"",$F$4,$D$4)&"_8",가이드배합비DB!$A:$G,4,FALSE()),"") -> 0 | F14: =IFERROR(VLOOKUP($B$4&"_"&IF($F$4<>"",$F$4,$D$4)&"_8",가이드배합비DB!$A:$G,5,FALSE()),"") -> 0 | G14: =IFERROR(VLOOKUP($B$4&"_"&IF($F$4<>"",$F$4,$D$4)&"_8",가이드배합비DB!$A:$G,6,FALSE()),"") -> 0 | H14: =IFERROR(VLOOKUP($B$4&"_"&IF($F$4<>"",$F$4,$D$4)&"_8",가이드배합비DB!$A:$G,7,FALSE()),"") -> 0 | I14: =IFERROR(VLOOKUP(C14,원료DB!$D:$Q,2,FALSE()),"") | J14: =IFERROR(VLOOKUP(C14,원료DB!$D:$Q,4,FALSE()),"") | K14: =IFERROR(VLOOKUP(C14,원료DB!$D:$Q,5,FALSE()),"") | N14: =IFERROR(VLOOKUP(C14,원료DB!$D:$Q,9,FALSE()),"") | O14: =IFERROR(D14/100*I14,0) -> 0 | P14: =IFERROR(D14/100*J14,0) -> 0 | Q14: =IFERROR(D14/100*K14,0) -> 0 | R14: =IFERROR(D14/100*N14,0) -> 0 | S14: =IFERROR(D14*10,0) -> 0
A15: 9 | B15: 안정제/ 호료 | C15: 펙틴(HM/고메톡실) | D15: 0.15 | E15: =IFERROR(VLOOKUP($B$4&"_"&IF($F$4<>"",$F$4,$D$4)&"_9",가이드배합비DB!$A:$G,4,FALSE()),"") -> 펙틴(HM/고메톡실) | F15: =IFERROR(VLOOKUP($B$4&"_"&IF($F$4<>"",$F$4,$D$4)&"_9",가이드배합비DB!$A:$G,5,FALSE()),"") -> 0.15 | G15: =IFERROR(VLOOKUP($B$4&"_"&IF($F$4<>"",$F$4,$D$4)&"_9",가이드배합비DB!$A:$G,6,FALSE()),"") -> 펙틴(HM/고메톡실) | H15: =IFERROR(VLOOKUP($B$4&"_"&IF($F$4<>"",$F$4,$D$4)&"_9",가이드배합비DB!$A:$G,7,FALSE()),"") -> 0.15 | I15: =IFERROR(VLOOKUP(C15,원료DB!$D:$Q,2,FALSE()),"") -> — | J15: =IFERROR(VLOOKUP(C15,원료DB!$D:$Q,4,FALSE()),"") -> — | K15: =IFERROR(VLOOKUP(C15,원료DB!$D:$Q,5,FALSE()),"") -> 0 | N15: =IFERROR(VLOOKUP(C15,원료DB!$D:$Q,9,FALSE()),"") -> 25000 | O15: =IFERROR(D15/100*I15,0) -> 0 | P15: =IFERROR(D15/100*J15,0) -> 0 | Q15: =IFERROR(D15/100*K15,0) -> 0 | R15: =IFERROR(D15/100*N15,0) -> 37.5 | S15: =IFERROR(D15*10,0) -> 1.5
A16: 10 | E16: =IFERROR(VLOOKUP($B$4&"_"&IF($F$4<>"",$F$4,$D$4)&"_10",가이드배합비DB!$A:$G,4,FALSE()),"") -> 0 | F16: =IFERROR(VLOOKUP($B$4&"_"&IF($F$4<>"",$F$4,$D$4)&"_10",가이드배합비DB!$A:$G,5,FALSE()),"") -> 0 | G16: =IFERROR(VLOOKUP($B$4&"_"&IF($F$4<>"",$F$4,$D$4)&"_10",가이드배합비DB!$A:$G,6,FALSE()),"") -> 0 | H16: =IFERROR(VLOOKUP($B$4&"_"&IF($F$4<>"",$F$4,$D$4)&"_10",가이드배합비DB!$A:$G,7,FALSE()),"") -> 0 | I16: =IFERROR(VLOOKUP(C16,원료DB!$D:$Q,2,FALSE()),"") | J16: =IFERROR(VLOOKUP(C16,원료DB!$D:$Q,4,FALSE()),"") | K16: =IFERROR(VLOOKUP(C16,원료DB!$D:$Q,5,FALSE()),"") | N16: =IFERROR(VLOOKUP(C16,원료DB!$D:$Q,9,FALSE()),"") | O16: =IFERROR(D16/100*I16,0) -> 0 | P16: =IFERROR(D16/100*J16,0) -> 0 | Q16: =IFERROR(D16/100*K16,0) -> 0 | R16: =IFERROR(D16/100*N16,0) -> 0 | S16: =IFERROR(D16*10,0) -> 0
A17: 11 | E17: =IFERROR(VLOOKUP($B$4&"_"&IF($F$4<>"",$F$4,$D$4)&"_11",가이드배합비DB!$A:$G,4,FALSE()),"") -> 0 | F17: =IFERROR(VLOOKUP($B$4&"_"&IF($F$4<>"",$F$4,$D$4)&"_11",가이드배합비DB!$A:$G,5,FALSE()),"") -> 0 | G17: =IFERROR(VLOOKUP($B$4&"_"&IF($F$4<>"",$F$4,$D$4)&"_11",가이드배합비DB!$A:$G,6,FALSE()),"") -> 0 | H17: =IFERROR(VLOOKUP($B$4&"_"&IF($F$4<>"",$F$4,$D$4)&"_11",가이드배합비DB!$A:$G,7,FALSE()),"") -> 0 | I17: =IFERROR(VLOOKUP(C17,원료DB!$D:$Q,2,FALSE()),"") | J17: =IFERROR(VLOOKUP(C17,원료DB!$D:$Q,4,FALSE()),"") | K17: =IFERROR(VLOOKUP(C17,원료DB!$D:$Q,5,FALSE()),"") | N17: =IFERROR(VLOOKUP(C17,원료DB!$D:$Q,9,FALSE()),"") | O17: =IFERROR(D17/100*I17,0) -> 0 | P17: =IFERROR(D17/100*J17,0) -> 0 | Q17: =IFERROR(D17/100*K17,0) -> 0 | R17: =IFERROR(D17/100*N17,0) -> 0 | S17: =IFERROR(D17*10,0) -> 0
A18: 12 | E18: =IFERROR(VLOOKUP($B$4&"_"&IF($F$4<>"",$F$4,$D$4)&"_12",가이드배합비DB!$A:$G,4,FALSE()),"") -> 0 | F18: =IFERROR(VLOOKUP($B$4&"_"&IF($F$4<>"",$F$4,$D$4)&"_12",가이드배합비DB!$A:$G,5,FALSE()),"") -> 0 | G18: =IFERROR(VLOOKUP($B$4&"_"&IF($F$4<>"",$F$4,$D$4)&"_12",가이드배합비DB!$A:$G,6,FALSE()),"") -> 0 | H18: =IFERROR(VLOOKUP($B$4&"_"&IF($F$4<>"",$F$4,$D$4)&"_12",가이드배합비DB!$A:$G,7,FALSE()),"") -> 0 | I18: =IFERROR(VLOOKUP(C18,원료DB!$D:$Q,2,FALSE()),"") | J18: =IFERROR(VLOOKUP(C18,원료DB!$D:$Q,4,FALSE()),"") | K18: =IFERROR(VLOOKUP(C18,원료DB!$D:$Q,5,FALSE()),"") | N18: =IFERROR(VLOOKUP(C18,원료DB!$D:$Q,9,FALSE()),"") | O18: =IFERROR(D18/100*I18,0) -> 0 | P18: =IFERROR(D18/100*J18,0) -> 0 | Q18: =IFERROR(D18/100*K18,0) -> 0 | R18: =IFERROR(D18/100*N18,0) -> 0 | S18: =IFERROR(D18*10,0) -> 0
A19: 13 | B19: 기타 자재 | C19: 구연산(무수) | D19: 0.15 | E19: =IFERROR(VLOOKUP($B$4&"_"&IF($F$4<>"",$F$4,$D$4)&"_13",가이드배합비DB!$A:$G,4,FALSE()),"") -> 구연산(무수) | F19: =IFERROR(VLOOKUP($B$4&"_"&IF($F$4<>"",$F$4,$D$4)&"_13",가이드배합비DB!$A:$G,5,FALSE()),"") -> 0.15 | G19: =IFERROR(VLOOKUP($B$4&"_"&IF($F$4<>"",$F$4,$D$4)&"_13",가이드배합비DB!$A:$G,6,FALSE()),"") -> 구연산(무수) | H19: =IFERROR(VLOOKUP($B$4&"_"&IF($F$4<>"",$F$4,$D$4)&"_13",가이드배합비DB!$A:$G,7,FALSE()),"") -> 0.16 | I19: =IFERROR(VLOOKUP(C19,원료DB!$D:$Q,2,FALSE()),"") -> — | J19: =IFERROR(VLOOKUP(C19,원료DB!$D:$Q,4,FALSE()),"") -> — | K19: =IFERROR(VLOOKUP(C19,원료DB!$D:$Q,5,FALSE()),"") -> 0 | N19: =IFERROR(VLOOKUP(C19,원료DB!$D:$Q,9,FALSE()),"") -> 2500 | O19: =IFERROR(D19/100*I19,0) -> 0 | P19: =IFERROR(D19/100*J19,0) -> 0 | Q19: =IFERROR(D19/100*K19,0) -> 0 | R19: =IFERROR(D19/100*N19,0) -> 3.75 | S19: =IFERROR(D19*10,0) -> 1.5
A20: 14 | C20: 사과향 | D20: 0.1 | E20: =IFERROR(VLOOKUP($B$4&"_"&IF($F$4<>"",$F$4,$D$4)&"_14",가이드배합비DB!$A:$G,4,FALSE()),"") -> 사과향 | F20: =IFERROR(VLOOKUP($B$4&"_"&IF($F$4<>"",$F$4,$D$4)&"_14",가이드배합비DB!$A:$G,5,FALSE()),"") -> 0.1 | G20: =IFERROR(VLOOKUP($B$4&"_"&IF($F$4<>"",$F$4,$D$4)&"_14",가이드배합비DB!$A:$G,6,FALSE()),"") -> 니코틴산아미드 | H20: =IFERROR(VLOOKUP($B$4&"_"&IF($F$4<>"",$F$4,$D$4)&"_14",가이드배합비DB!$A:$G,7,FALSE()),"") -> 0.003 | I20: =IFERROR(VLOOKUP(C20,원료DB!$D:$Q,2,FALSE()),"") -> — | J20: =IFERROR(VLOOKUP(C20,원료DB!$D:$Q,4,FALSE()),"") -> — | K20: =IFERROR(VLOOKUP(C20,원료DB!$D:$Q,5,FALSE()),"") -> 0 | N20: =IFERROR(VLOOKUP(C20,원료DB!$D:$Q,9,FALSE()),"") -> 40000 | O20: =IFERROR(D20/100*I20,0) -> 0 | P20: =IFERROR(D20/100*J20,0) -> 0 | Q20: =IFERROR(D20/100*K20,0) -> 0 | R20: =IFERROR(D20/100*N20,0) -> 40 | S20: =IFERROR(D20*10,0) -> 1
A21: 15 | C21: 아스코르빈산(비타민C) | D21: 0.05 | E21: =IFERROR(VLOOKUP($B$4&"_"&IF($F$4<>"",$F$4,$D$4)&"_15",가이드배합비DB!$A:$G,4,FALSE()),"") -> 아스코르빈산(비타민C) | F21: =IFERROR(VLOOKUP($B$4&"_"&IF($F$4<>"",$F$4,$D$4)&"_15",가이드배합비DB!$A:$G,5,FALSE()),"") -> 0.05 | G21: =IFERROR(VLOOKUP($B$4&"_"&IF($F$4<>"",$F$4,$D$4)&"_15",가이드배합비DB!$A:$G,6,FALSE()),"") -> 아스코르빈산(비타민C) | H21: =IFERROR(VLOOKUP($B$4&"_"&IF($F$4<>"",$F$4,$D$4)&"_15",가이드배합비DB!$A:$G,7,FALSE()),"") -> 0.04 | I21: =IFERROR(VLOOKUP(C21,원료DB!$D:$Q,2,FALSE()),"") -> — | J21: =IFERROR(VLOOKUP(C21,원료DB!$D:$Q,4,FALSE()),"") -> — | K21: =IFERROR(VLOOKUP(C21,원료DB!$D:$Q,5,FALSE()),"") -> 0 | N21: =IFERROR(VLOOKUP(C21,원료DB!$D:$Q,9,FALSE()),"") -> 12000 | O21: =IFERROR(D21/100*I21,0) -> 0 | P21: =IFERROR(D21/100*J21,0) -> 0 | Q21: =IFERROR(D21/100*K21,0) -> 0 | R21: =IFERROR(D21/100*N21,0) -> 6 | S21: =IFERROR(D21*10,0) -> 0.5
A22: 16 | C22: 베타카로틴(합성) | D22: 0.02 | E22: =IFERROR(VLOOKUP($B$4&"_"&IF($F$4<>"",$F$4,$D$4)&"_16",가이드배합비DB!$A:$G,4,FALSE()),"") -> 베타카로틴(합성) | F22: =IFERROR(VLOOKUP($B$4&"_"&IF($F$4<>"",$F$4,$D$4)&"_16",가이드배합비DB!$A:$G,5,FALSE()),"") -> 0.02 | G22: =IFERROR(VLOOKUP($B$4&"_"&IF($F$4<>"",$F$4,$D$4)&"_16",가이드배합비DB!$A:$G,6,FALSE()),"") -> 0 | H22: =IFERROR(VLOOKUP($B$4&"_"&IF($F$4<>"",$F$4,$D$4)&"_16",가이드배합비DB!$A:$G,7,FALSE()),"") -> 0 | I22: =IFERROR(VLOOKUP(C22,원료DB!$D:$Q,2,FALSE()),"") -> — | J22: =IFERROR(VLOOKUP(C22,원료DB!$D:$Q,4,FALSE()),"") -> — | K22: =IFERROR(VLOOKUP(C22,원료DB!$D:$Q,5,FALSE()),"") -> 0 | N22: =IFERROR(VLOOKUP(C22,원료DB!$D:$Q,9,FALSE()),"") -> 25000 | O22: =IFERROR(D22/100*I22,0) -> 0 | P22: =IFERROR(D22/100*J22,0) -> 0 | Q22: =IFERROR(D22/100*K22,0) -> 0 | R22: =IFERROR(D22/100*N22,0) -> 5 | S22: =IFERROR(D22*10,0) -> 0.2
A23: 17 | E23: =IFERROR(VLOOKUP($B$4&"_"&IF($F$4<>"",$F$4,$D$4)&"_17",가이드배합비DB!$A:$G,4,FALSE()),"") -> 0 | F23: =IFERROR(VLOOKUP($B$4&"_"&IF($F$4<>"",$F$4,$D$4)&"_17",가이드배합비DB!$A:$G,5,FALSE()),"") -> 0 | G23: =IFERROR(VLOOKUP($B$4&"_"&IF($F$4<>"",$F$4,$D$4)&"_17",가이드배합비DB!$A:$G,6,FALSE()),"") -> 0 | H23: =IFERROR(VLOOKUP($B$4&"_"&IF($F$4<>"",$F$4,$D$4)&"_17",가이드배합비DB!$A:$G,7,FALSE()),"") -> 0 | I23: =IFERROR(VLOOKUP(C23,원료DB!$D:$Q,2,FALSE()),"") | J23: =IFERROR(VLOOKUP(C23,원료DB!$D:$Q,4,FALSE()),"") | K23: =IFERROR(VLOOKUP(C23,원료DB!$D:$Q,5,FALSE()),"") | N23: =IFERROR(VLOOKUP(C23,원료DB!$D:$Q,9,FALSE()),"") | O23: =IFERROR(D23/100*I23,0) -> 0 | P23: =IFERROR(D23/100*J23,0) -> 0 | Q23: =IFERROR(D23/100*K23,0) -> 0 | R23: =IFERROR(D23/100*N23,0) -> 0 | S23: =IFERROR(D23*10,0) -> 0
A24: 18 | E24: =IFERROR(VLOOKUP($B$4&"_"&IF($F$4<>"",$F$4,$D$4)&"_18",가이드배합비DB!$A:$G,4,FALSE()),"") -> 0 | F24: =IFERROR(VLOOKUP($B$4&"_"&IF($F$4<>"",$F$4,$D$4)&"_18",가이드배합비DB!$A:$G,5,FALSE()),"") -> 0 | G24: =IFERROR(VLOOKUP($B$4&"_"&IF($F$4<>"",$F$4,$D$4)&"_18",가이드배합비DB!$A:$G,6,FALSE()),"") -> 0 | H24: =IFERROR(VLOOKUP($B$4&"_"&IF($F$4<>"",$F$4,$D$4)&"_18",가이드배합비DB!$A:$G,7,FALSE()),"") -> 0 | I24: =IFERROR(VLOOKUP(C24,원료DB!$D:$Q,2,FALSE()),"") | J24: =IFERROR(VLOOKUP(C24,원료DB!$D:$Q,4,FALSE()),"") | K24: =IFERROR(VLOOKUP(C24,원료DB!$D:$Q,5,FALSE()),"") | N24: =IFERROR(VLOOKUP(C24,원료DB!$D:$Q,9,FALSE()),"") | O24: =IFERROR(D24/100*I24,0) -> 0 | P24: =IFERROR(D24/100*J24,0) -> 0 | Q24: =IFERROR(D24/100*K24,0) -> 0 | R24: =IFERROR(D24/100*N24,0) -> 0 | S24: =IFERROR(D24*10,0) -> 0
A25: 19 | E25: =IFERROR(VLOOKUP($B$4&"_"&IF($F$4<>"",$F$4,$D$4)&"_19",가이드배합비DB!$A:$G,4,FALSE()),"") -> 0 | F25: =IFERROR(VLOOKUP($B$4&"_"&IF($F$4<>"",$F$4,$D$4)&"_19",가이드배합비DB!$A:$G,5,FALSE()),"") -> 0 | G25: =IFERROR(VLOOKUP($B$4&"_"&IF($F$4<>"",$F$4,$D$4)&"_19",가이드배합비DB!$A:$G,6,FALSE()),"") -> 0 | H25: =IFERROR(VLOOKUP($B$4&"_"&IF($F$4<>"",$F$4,$D$4)&"_19",가이드배합비DB!$A:$G,7,FALSE()),"") -> 0 | I25: =IFERROR(VLOOKUP(C25,원료DB!$D:$Q,2,FALSE()),"") | J25: =IFERROR(VLOOKUP(C25,원료DB!$D:$Q,4,FALSE()),"") | K25: =IFERROR(VLOOKUP(C25,원료DB!$D:$Q,5,FALSE()),"") | N25: =IFERROR(VLOOKUP(C25,원료DB!$D:$Q,9,FALSE()),"") | O25: =IFERROR(D25/100*I25,0) -> 0 | P25: =IFERROR(D25/100*J25,0) -> 0 | Q25: =IFERROR(D25/100*K25,0) -> 0 | R25: =IFERROR(D25/100*N25,0) -> 0 | S25: =IFERROR(D25*10,0) -> 0
A26: 20 | B26: 정제수 | C26: 정제수 | D26: =100-SUM(D7:D25) -> 77.53 | E26: 정제수 | F26: =IFERROR(VLOOKUP($B$4&"_"&IF($F$4<>"",$F$4,$D$4)&"_20",가이드배합비DB!$A:$G,5,FALSE()),"") -> 77.53 | G26: 정제수 | H26: =IFERROR(VLOOKUP($B$4&"_"&IF($F$4<>"",$F$4,$D$4)&"_20",가이드배합비DB!$A:$G,7,FALSE()),"") -> 75.15 | I26: 0 | J26: 0 | K26: 0 | N26: 2 | O26: 0 | P26: 0 | Q26: 0 | R26: =D26/100*N26 -> 1.5506 | S26: =D26*10 -> 775.3
A27: 합 계 | D27: =SUM(D7:D26) -> 100 | F27: =SUM(F7:F26) -> 100 | H27: =SUM(H7:H26) -> 100.003 | O27: =SUM(O7:O26) -> 13.188 | P27: =SUM(P7:P26) -> 0.2925 | Q27: =SUM(Q7:Q26) -> 0.09 | R27: =SUM(R7:R26) -> 500.3006 | S27: =SUM(S7:S26) -> 1000
C28: 원재료함량 | D28: =SUM(D7:D10)/100 -> 0.13 | N28: 농축율 | O28: =IF(O5>0,O27/O5,"") -> 1.1989091
A30: ▶ 시뮬레이션 결과 요약
A31: 배합비 합계(%) | D31: =D27 -> 100 | E31: =IF(ABS(D27-100)<0.1,"✅ 100% 충족","⚠️ "&ROUND(D27,1)&"% - 조정필요") -> ✅ 100% 충족
A32: 예상 당도(Bx) | D32: =O27 -> 13.188 | E32: =IFERROR(IF(VLOOKUP($B$4,음료규격기준!$B:$O,9,FALSE())="","ℹ️ 규격없음",IF(AND(D32>=VLOOKUP($B$4,음료규격기준!$B:$O,9,FALSE()),D32<=VLOOKUP($B$4,음료규격기준!$B:$O,10,FALSE())),"✅ 규격이내("&VLOOKUP($B$4,음료규격기준!$B:$I,2,FALSE())&"°)",IF(D32<VLOOKUP($B$4,음료규격기준!$B:$O,9,FALSE()),"⚠️ 하한미달("&VLOOKUP($B$4,음료규격기준!$B:$I,2,FALSE())&"°)","⚠️ 상한초과("&VLOOKUP($B$4,음료규격기준!$B:$I,2,FALSE())&"°)"))),"ℹ️ 참조불가") -> ⚠️ 상한초과(8~13°)
A33: 예상 산도(%) | D33: =P27 -> 0.2925 | E33: =IFERROR(IF(VLOOKUP($B$4,음료규격기준!$B:$O,13,FALSE())="","ℹ️ 산도규격없음",IF(AND(D33>=VLOOKUP($B$4,음료규격기준!$B:$O,13,FALSE()),D33<=VLOOKUP($B$4,음료규격기준!$B:$O,14,FALSE())),"✅ 규격이내("&VLOOKUP($B$4,음료규격기준!$B:$I,4,FALSE())&"%)","⚠️ 규격벗어남("&VLOOKUP($B$4,음료규격기준!$B:$I,4,FALSE())&"%)")),"ℹ️ 산도규격없음") -> ✅ 규격이내(0.2~1.0%)
A34: 예상 감미도 | D34: =Q27 -> 0.09
A35: 원재료비(원/kg) | D35: =R27 -> 500.3006 | E35: =IF(R5>0,IF(R27<=R5,"✅ 목표이내","⚠️ 목표("&TEXT(R5,"#,##0")&"원) 초과 +"&TEXT(R27-R5,"#,##0")&"원"),"") -> ✅ 목표이내
A36: 원재료비(원/병) | D36: =R27*J3/1000 -> 500.3006
A37: 원료 사용 종류(개) | D37: =COUNTA(C7:C26) -> 10
A38: 정제수 비율(%) | D38: =D26 -> 77.53 | E38: =IF(D26>=50,"✅ 적정(50%이상)",IF(D26>=30,"ℹ️ 보통","⚠️ 정제수 부족")) -> ✅ 적정(50%이상)
A39: pH 규격 (참고) | D39: — | E39: =IFERROR("ℹ️ pH규격: "&VLOOKUP($B$4,음료규격기준!$B:$I,3,FALSE())&" → 실측 필요","") -> ℹ️ pH규격: 3.0~4.5 → 실측 필요
A40: 원재료함량 vs 과즙기준 | D40: =D28 -> 0.13 | E40: =IFERROR("ℹ️ 과즙기준: "&VLOOKUP($B$4,음료규격기준!$B:$I,5,FALSE())&" | 현재: "&TEXT(D28*100,"0.0")&"%","") -> ℹ️ 과즙기준: 10~99% | 현재: 13.0%
A42: ▶ 사용방법
...

Sheet 원가계산서
A1: 음료 제품 원가계산서 (Cost Calculation Sheet)
A3: 제품명 | B3: =배합시뮬레이터!E3 -> 0 | D3: 용량(ml) | E3: =배합시뮬레이터!J3 -> 1000 | G3: 음료유형 | H3: (입력)
A4: 월생산량(병) | B4: 100000 | D4: 연생산량(병) | E4: =B4*12 -> 1200000 | G4: 포장용기 | H4: PET
A6: ① 원재료비 (배합시뮬레이터 자동연동)
A7: No | B7: 항목 | C7: 산출근거 | D7: 단가(원/kg) | E7: 사용량(kg/병) | F7: 비용(원/병) | G7: 비용(원/kg제품) | H7: 비고
A8: 1 | B8: =IFERROR(IF(배합시뮬레이터!C7="","",배합시뮬레이터!C7),"") -> 사과농축과즙(70Brix) | C8: =IFERROR(IF(배합시뮬레이터!D7=0,"",TEXT(배합시뮬레이터!D7,"0.00")&"%"),"") -> 8.00% | D8: =IFERROR(배합시뮬레이터!N7,0) -> 3500 | E8: =IFERROR(배합시뮬레이터!D7/100*$E$3/1000,0) -> 0.08 | F8: =IFERROR(D8*E8,0) -> 280 | G8: =IFERROR(배합시뮬레이터!R7,0) -> 280
A9: 2 | B9: =IFERROR(IF(배합시뮬레이터!C8="","",배합시뮬레이터!C8),"") -> 사과페이스트 | C9: =IFERROR(IF(배합시뮬레이터!D8=0,"",TEXT(배합시뮬레이터!D8,"0.00")&"%"),"") -> 5.00% | D9: =IFERROR(배합시뮬레이터!N8,0) -> 650 | E9: =IFERROR(배합시뮬레이터!D8/100*$E$3/1000,0) -> 0.05 | F9: =IFERROR(D9*E9,0) -> 32.5 | G9: =IFERROR(배합시뮬레이터!R8,0) -> 32.5
A10: 3 | B10: =IFERROR(IF(배합시뮬레이터!C9="","",배합시뮬레이터!C9),"") | C10: =IFERROR(IF(배합시뮬레이터!D9=0,"",TEXT(배합시뮬레이터!D9,"0.00")&"%"),"") | D10: =IFERROR(배합시뮬레이터!N9,0) | E10: =IFERROR(배합시뮬레이터!D9/100*$E$3/1000,0) -> 0 | F10: =IFERROR(D10*E10,0) -> 0 | G10: =IFERROR(배합시뮬레이터!R9,0) -> 0
A11: 4 | B11: =IFERROR(IF(배합시뮬레이터!C10="","",배합시뮬레이터!C10),"") | C11: =IFERROR(IF(배합시뮬레이터!D10=0,"",TEXT(배합시뮬레이터!D10,"0.00")&"%"),"") | D11: =IFERROR(배합시뮬레이터!N10,0) | E11: =IFERROR(배합시뮬레이터!D10/100*$E$3/1000,0) -> 0 | F11: =IFERROR(D11*E11,0) -> 0 | G11: =IFERROR(배합시뮬레이터!R10,0) -> 0
A12: 5 | B12: =IFERROR(IF(배합시뮬레이터!C11="","",배합시뮬레이터!C11),"") -> 액상과당(HFCS55) | C12: =IFERROR(IF(배합시뮬레이터!D11=0,"",TEXT(배합시뮬레이터!D11,"0.00")&"%"),"") -> 7.00% | D12: =IFERROR(배합시뮬레이터!N11,0) -> 1000 | E12: =IFERROR(배합시뮬레이터!D11/100*$E$3/1000,0) -> 0.07 | F12: =IFERROR(D12*E12,0) -> 70 | G12: =IFERROR(배합시뮬레이터!R11,0) -> 70
A13: 6 | B13: =IFERROR(IF(배합시뮬레이터!C12="","",배합시뮬레이터!C12),"") -> 백설탕(정제당) | C13: =IFERROR(IF(배합시뮬레이터!D12=0,"",TEXT(배합시뮬레이터!D12,"0.00")&"%"),"") -> 2.00% | D13: =IFERROR(배합시뮬레이터!N12,0) -> 1200 | E13: =IFERROR(배합시뮬레이터!D12/100*$E$3/1000,0) -> 0.02 | F13: =IFERROR(D13*E13,0) -> 24 | G13: =IFERROR(배합시뮬레이터!R12,0) -> 24
A14: 7 | B14: =IFERROR(IF(배합시뮬레이터!C13="","",배합시뮬레이터!C13),"") | C14: =IFERROR(IF(배합시뮬레이터!D13=0,"",TEXT(배합시뮬레이터!D13,"0.00")&"%"),"") | D14: =IFERROR(배합시뮬레이터!N13,0) | E14: =IFERROR(배합시뮬레이터!D13/100*$E$3/1000,0) -> 0 | F14: =IFERROR(D14*E14,0) -> 0 | G14: =IFERROR(배합시뮬레이터!R13,0) -> 0
A15: 8 | B15: =IFERROR(IF(배합시뮬레이터!C14="","",배합시뮬레이터!C14),"") | C15: =IFERROR(IF(배합시뮬레이터!D14=0,"",TEXT(배합시뮬레이터!D14,"0.00")&"%"),"") | D15: =IFERROR(배합시뮬레이터!N14,0) | E15: =IFERROR(배합시뮬레이터!D14/100*$E$3/1000,0) -> 0 | F15: =IFERROR(D15*E15,0) -> 0 | G15: =IFERROR(배합시뮬레이터!R14,0) -> 0
A16: 9 | B16: =IFERROR(IF(배합시뮬레이터!C15="","",배합시뮬레이터!C15),"") -> 펙틴(HM/고메톡실) | C16: =IFERROR(IF(배합시뮬레이터!D15=0,"",TEXT(배합시뮬레이터!D15,"0.00")&"%"),"") -> 0.15% | D16: =IFERROR(배합시뮬레이터!N15,0) -> 25000 | E16: =IFERROR(배합시뮬레이터!D15/100*$E$3/1000,0) -> 0.0015 | F16: =IFERROR(D16*E16,0) -> 37.5 | G16: =IFERROR(배합시뮬레이터!R15,0) -> 37.5
A17: 10 | B17: =IFERROR(IF(배합시뮬레이터!C16="","",배합시뮬레이터!C16),"") | C17: =IFERROR(IF(배합시뮬레이터!D16=0,"",TEXT(배합시뮬레이터!D16,"0.00")&"%"),"") | D17: =IFERROR(배합시뮬레이터!N16,0) | E17: =IFERROR(배합시뮬레이터!D16/100*$E$3/1000,0) -> 0 | F17: =IFERROR(D17*E17,0) -> 0 | G17: =IFERROR(배합시뮬레이터!R16,0) -> 0
A18: 11 | B18: =IFERROR(IF(배합시뮬레이터!C17="","",배합시뮬레이터!C17),"") | C18: =IFERROR(IF(배합시뮬레이터!D17=0,"",TEXT(배합시뮬레이터!D17,"0.00")&"%"),"") | D18: =IFERROR(배합시뮬레이터!N17,0) | E18: =IFERROR(배합시뮬레이터!D17/100*$E$3/1000,0) -> 0 | F18: =IFERROR(D18*E18,0) -> 0 | G18: =IFERROR(배합시뮬레이터!R17,0) -> 0
A19: 12 | B19: =IFERROR(IF(배합시뮬레이터!C18="","",배합시뮬레이터!C18),"") | C19: =IFERROR(IF(배합시뮬레이터!D18=0,"",TEXT(배합시뮬레이터!D18,"0.00")&"%"),"") | D19: =IFERROR(배합시뮬레이터!N18,0) | E19: =IFERROR(배합시뮬레이터!D18/100*$E$3/1000,0) -> 0 | F19: =IFERROR(D19*E19,0) -> 0 | G19: =IFERROR(배합시뮬레이터!R18,0) -> 0
... A27: 20 | B27: =IFERROR(IF(배합시뮬레이터!C26="","",배합시뮬레이터!C26),"") -> 정제수 | C27: =IFERROR(IF(배합시뮬레이터!D26=0,"",TEXT(배합시뮬레이터!D26,"0.00")&"%"),"") -> 77.53% | D27: =IFERROR(배합시뮬레이터!N26,0) -> 2 | E27: =IFERROR(배합시뮬레이터!D26/100*$E$3/1000,0) -> 0.7753 | F27: =IFERROR(D27*E27,0) -> 1.5506 | G27: =IFERROR(배합시뮬레이터!R26,0) -> 1.5506
A28: 원재료비 소계 | F28: =SUM(F8:F27) -> 500.3006 | G28: =SUM(G8:G27) -> 500.3006
A30: ② 포장재비
A31: No | B31: 항목 | C31: 산출근거 | D31: 단가(원/kg) | E31: 사용량(kg/병) | F31: 비용(원/병) | G31: 비용(원/kg제품) | H31: 비고
A32: 1 | B32: PET 용기 | C32: 용기단가 | D32: 45 | E32: 1 | F32: =D32*E32 -> 45 | G32: =F32/($E$3/1000) -> 45 | H32: PET 350ml 기준
A33: 2 | B33: PE 캡 (28mm) | C33: 캡단가 | D33: 8 | E33: 1 | F33: =D33*E33 -> 8 | G33: =F33/($E$3/1000) -> 8
A34: 3 | B34: 수축라벨 (PVC/PET) | C34: 라벨단가 | D34: 12 | E34: 1 | F34: =D34*E34 -> 12 | G34: =F34/($E$3/1000) -> 12 | H34: 열수축
A35: 4 | B35: 카톤박스 (24입) | C35: 박스단가/24 | D35: 50 | E35: 1 | F35: =D35*E35 -> 50 | G35: =F35/($E$3/1000) -> 50 | H35: 1200원/24입
A36: 5 | B36: 빨대/스트로우 | C36: 해당시 | D36: 0 | E36: 0 | F36: =D36*E36 -> 0 | G36: =F36/($E$3/1000) -> 0 | H36: 해당없음시 0
A37: 6 | B37: 쉬링크랩 | C37: 팩당가 | D37: 5 | E37: 1 | F37: =D37*E37 -> 5 | G37: =F37/($E$3/1000) -> 5
A38: 포장재비 소계 | F38: =SUM(F32:F37) -> 120 | G38: =SUM(G32:G37) -> 120
A40: ③ 제조경비 (가공비)
A41: No | B41: 항목 | C41: 산출근거 | D41: 단가(원/kg) | E41: 사용량(kg/병) | F41: 비용(원/병) | G41: 비용(원/kg제품) | H41: 비고
A42: 1 | B42: 인건비(직접) | C42: 작업자 시급×시간/생산량 | F42: 15 | G42: =F42/($E$3/1000) -> 15
A43: 2 | B43: 인건비(간접) | C43: 관리/품질인력 배분 | F43: 5 | G43: =F43/($E$3/1000) -> 5
A44: 3 | B44: 전력비 | C44: 살균/냉각/균질/충전 | F44: 8 | G44: =F44/($E$3/1000) -> 8
A45: 4 | B45: 용수비 | C45: 정제수제조+세척 | F45: 2 | G45: =F45/($E$3/1000) -> 2
A46: 5 | B46: 스팀비(열에너지) | C46: UHT살균/CIP | F46: 5 | G46: =F46/($E$3/1000) -> 5
A47: 6 | B47: 냉각비 | C47: 냉각수/냉매 | F47: 3 | G47: =F47/($E$3/1000) -> 3
A48: 7 | B48: 압축공기/CO₂ | C48: 탄산주입/공압 | F48: 2 | G48: =F48/($E$3/1000) -> 2
A49: 8 | B49: 세척(CIP)비 | C49: CIP약품+용수+스팀 | F49: 3 | G49: =F49/($E$3/1000) -> 3
A50: 9 | B50: 품질검사비 | C50: 이화학/미생물 | F50: 2 | G50: =F50/($E$3/1000) -> 2
A51: 10 | B51: 설비감가상각 | C51: 연감가/연생산량 | F51: 10 | G51: =F51/($E$3/1000) -> 10
...

Sheet 자재SPEC참조
B1: 당류 Bx,감미 | H1: 부자재 Bx, 산도
B2: 당류 | C2: Bx | D2: 감미도 | E2: 감미료 | F2: 감미도 | H2: 안정제 | I2: Bx | J2: 부자재 | K2: Bx | L2: 산도
B3: 백설탕 | C3: 100 | D3: 1 | E3: 사카린 | F3: 300 | H3: 전분 | I3: 90 | J3: 구연산 | K3: 80 | L3: 100
B4: 함수결정포도당 | C4: 90 | D4: 0.6 | E4: 아세설팜 | F4: 200 | H4: 펙틴 | I4: 95 | J4: 사과산 | K4: 85 | L4: 95
B5: 물엿 | C5: 82 | D5: 0.4 | E5: 수크랄로스 | F5: 600 | H5: 검류 | I5: 80 | J5: 글루코노델타락톤 | K5: 100 | L5: 55
B6: 프락토올리고당 | C6: 75 | D6: 0.6 | E6: 네오헤스피리딘 디히드로칼콘 | F6: 1500 | J6: 비타민C | K6: 100 | L6: 40
B7: 갈락토올리고당 | C7: 75 | D7: 0.4 | E7: 스테비아 감미료 | F7: 200 | J7: 구연산삼나트륨 | K7: 100
B8: 이소말토올리고당 | C8: 75 | D8: 0.5 | E8: 소마틴 | F8: 2500 | J8: 칼슘제제 | K8: 80
B9: 액상과당 | C9: 75 | D9: 1 | E9: 감초감미료(글리시리진) | F9: 100 | J9: 복합허브추출물 지 | K9: 95
B10: 말티톨 | C10: 70 | D10: 0.8 | E10: 모넬린 | F10: 3000 | J10: 향료(합성) | K10: 50
B11: D-소르비톨액 | C11: 68 | D11: 0.6 | E11: 사이클라메이트 | F11: 30 | J11: 향료(천연) | K11: 20~30
B12: 이성화당 | D12: 1 | E12: 아스파탐 | F12: 200 | J12: 색소(분말) | K12: 100
B13: 이성화유당 | D13: 0.6 | J13: 색소(액상) | K13: 60
B14: 말토스 | D14: 0.4
B15: 트레할로스 | D15: 0.4
B16: 결정과당 | D16: 1.2
B17: 말토올리고당 | D17: 0.2
B18: 파라티노스올리고당 | D18: 0.3
B19: 파라티노스 | D19: 0.5
B20: 파라티니톨 | D20: 0.1
B21: 에리스리톨 | D21: 0.7
B22: 환원물엿 | D22: 0.6
B23: 락티톨 | D23: 0.3
B24: 자이리톨 | D24: 0.5
B25: 과당 | D25: 0.7

Sheet 과일Brix참조
B1: Type of Juice | C1: 과일 이름 | D1: s/s Brix Value | G1: Type of Juice | H1: 과일 이름 | I1: s/s Brix Value
D2: 한국기준 | E2: FDA | I2: 한국기준 | J2: FDA
B3: Apple | C3: 사과 | D3: 10 이상 | E3: 11.5 | G3: Date | H3: 대추야자 | J3: 18.5
B4: Apricot | C4: 살구 | D4: 7 이상 | E4: 11.7 | G4: Dewberry | H4: 듀베리 | J4: 10
B5: Lemon | C5: 레몬 | D5: 7 이상 | E5: 4.5 | G5: Elderberry | H5: 엘더베리 | J5: 11
B6: Lime | C6: 라임 | D6: 10 이상 | E6: 4.5 | G6: Fig | H6: 무화과 | J6: 18.2
B7: Papaya | C7: 파파야 | D7: 9 이상 | E7: 11.5 | G7: Gooseberry | H7: 구스베리 | J7: 8.3
B8: Peach | C8: 복숭아 | D8: 7 이상 | E8: 10.5 | G8: Grape | H8: 포도 | J8: 16
B9: Pear | C9: 배 | D9: 8 이상 | E9: 12 | G9: Honeydew melon | H9: 멜론(허니듀) | J9: 9.6
B10: Plum | C10: 자두 | D10: 6 이상 | E10: 14.3 | G10: Kiwi | H10: 키위(양다래) | J10: 15.4
B11: Strawberry | C11: 딸기 | D11: 7 이상 | E11: 8 | G11: Grapefriut | H11: 자몽 | J11: 10
B12: Watermelon | C12: 수박 | D12: 9 이상 | E12: 7.8 | G12: Guava | H12: 구아바 | J12: 7.7
B13: Acerola | C13: 아세롤라 | E13: 6 | G13: Loganberry | H13: 로건베리 | J13: 10.5
B14: Asparagus | C14: 아스파라거스 | G14: Mango | H14: 망고 | J14: 13
B15: Banana | C15: 바나나 | E15: 22 | G15: Nectarine | H15: 천도복숭아 | J15: 11.8
B16: Beet (Red) | C16: 빨강사탕무우 | G16: Orange | H16: 오렌지 | J16: 11.8
B17: Bell Pepper (Red) | C17: 벨페퍼 | G17: Passion Fruit | H17: 패션프룻 | J17: 14
B18: Bilberry | C18: 빌베리 | G18: Pineapple | H18: 파인애플 | J18: 12.8
B19: Blackberry | C19: 블랙베리 | E19: 10 | G19: Pomegranate | H19: 석류 | J19: 16
B20: Blueberry | C20: 블루베리 | E20: 10 | G20: Prune | H20: 푸룬 | J20: 18.5
B21: Boysenberry | C21: 보이젠베리 | E21: 10 | G21: Quince | H21: 모과 | J21: 13.3
B22: Cantaloupe Melon | E22: 9.6 | G22: Raisin | H22: 건포도 | J22: 18.5
B23: Carambola (Strafruit) | C23: 스타프룻 | E23: 7.8 | G23: Raspberry (Black) | H23: 라스베리(블랙) | J23: 11.1
B24: Carrot | C24: 당근 | E24: 8 | G24: Raspberry (Red) | H24: 라스베리 | J24: 9.2
B25: Casaba Melon | C25: 멜론(카싸바) | E25: 7.5 | G25: Red Date | H25: 대추 | J25: 18.5
B26: Cashew (Caju) | C26: 캐쉬넛 | E26: 12 | G26: Rhubarb | H26: 러밥 | J26: 5.7
B27: Celery | C27: 샐러리 | E27: 3.1 | G27: Soursop | H27: 샤워솝 | J27: 16
B28: Cherry (Dark Sweet) | C28: 버찌 (DS) | E28: 20 | G28: Spinach | H28: 시금치 | J28: 3
B29: Cherry (Red Sour) | C29: 버찌 (RS) | E29: 14 | G29: Sweet Potato | H29: 고구마 | J29: 10
B30: Crab Apple | C30: 꽃사과, 야생 능금 | E30: 15.4 | G30: Tamarind | H30: 타마린드 | J30: 18
B31: Cranberry | C31: 크랜베리 | E31: 7.5 | G31: Tangerine | H31: 탠저린 | J31: 11.8
B32: Currant (Black) | C32: 까막까치밥 | E32: 11 | G32: Tomato | H32: 토마토 | J32: 5
B33: Currant (Red) | C33: 까치밥(레드) | E33: 10.5 | G33: Youngberry | H33: 영베리 | J33: 10

Sheet 가이드배합비DB
A1: 키(유형_맛_슬롯) | B1: 슬롯번호 | C1: 구분 | D1: AI추천_원료명 | E1: AI추천_배합비(%) | F1: 실제사례_원료명 | G1: 실제사례_배합비(%)
A2: 과·채음료_사과_1 | B2: 1 | C2: 원재료 | D2: 사과농축과즙(70Brix) | E2: 8 | F2: 사과농축과즙(70Brix) | G2: 3
A3: 과·채음료_사과_2 | B3: 2 | C3: 원재료 | D3: 사과페이스트 | E3: 5 | F3: 사과퓨레 | G3: 10
A4: 과·채음료_사과_3 | B4: 3 | C4: 원재료 | F4: 사과농축과즙(70Brix) | G4: 3
A5: 과·채음료_사과_4 | B5: 4 | C5: 원재료
A6: 과·채음료_사과_5 | B6: 5 | C6: 당류 | D6: 액상과당(HFCS55) | E6: 7 | F6: 프락토올리고당(FOS) | G6: 8.5
A7: 과·채음료_사과_6 | B7: 6 | C7: 당류 | D7: 백설탕(정제당) | E7: 2
A8: 과·채음료_사과_7 | B8: 7 | C8: 당류
A9: 과·채음료_사과_8 | B9: 8 | C9: 당류
A10: 과·채음료_사과_9 | B10: 9 | C10: 안정제 | D10: 펙틴(HM/고메톡실) | E10: 0.15 | F10: 펙틴(HM/고메톡실) | G10: 0.15
A11: 과·채음료_사과_10 | B11: 10 | C11: 안정제
A12: 과·채음료_사과_11 | B12: 11 | C12: 안정제
A13: 과·채음료_사과_12 | B13: 12 | C13: 안정제
A14: 과·채음료_사과_13 | B14: 13 | C14: 기타 | D14: 구연산(무수) | E14: 0.15 | F14: 구연산(무수) | G14: 0.16
A15: 과·채음료_사과_14 | B15: 14 | C15: 기타 | D15: 사과향 | E15: 0.1 | F15: 니코틴산아미드 | G15: 0.003
A16: 과·채음료_사과_15 | B16: 15 | C16: 기타 | D16: 아스코르빈산(비타민C) | E16: 0.05 | F16: 아스코르빈산(비타민C) | G16: 0.04
A17: 과·채음료_사과_16 | B17: 16 | C17: 기타 | D17: 베타카로틴(합성) | E17: 0.02
A18: 과·채음료_사과_17 | B18: 17 | C18: 기타
A19: 과·채음료_사과_18 | B19: 18 | C19: 기타
A20: 과·채음료_사과_19 | B20: 19 | C20: 기타
A21: 과·채음료_사과_20 | B21: 20 | C21: 정제수 | D21: 정제수 | E21: 77.53 | F21: 정제수 | G21: 75.15
A22: 과·채음료_딸기_1 | B22: 1 | C22: 원재료 | D22: 딸기농축과즙(65Brix) | E22: 3 | F22: 딸기농축과즙(65Brix) | G22: 4.2
A23: 과·채음료_딸기_2 | B23: 2 | C23: 원재료 | D23: 딸기퓨레 | E23: 17 | F23: 냉동딸기 | G23: 20
A24: 과·채음료_딸기_3 | B24: 3 | C24: 원재료
A25: 과·채음료_딸기_4 | B25: 4 | C25: 원재료
A26: 과·채음료_딸기_5 | B26: 5 | C26: 당류 | D26: 백설탕(정제당) | E26: 4 | F26: 백설탕(정제당) | G26: 45.5
A27: 과·채음료_딸기_6 | B27: 6 | C27: 당류 | D27: 액상과당(HFCS55) | E27: 5 | F27: 물엿(DE42) | G27: 5
A28: 과·채음료_딸기_7 | B28: 7 | C28: 당류
A29: 과·채음료_딸기_8 | B29: 8 | C29: 당류
A30: 과·채음료_딸기_9 | B30: 9 | C30: 안정제 | D30: 펙틴(HM/고메톡실) | E30: 0.15 | F30: 아미드펙틴(YF575) | G30: 1.4
A31: 과·채음료_딸기_10 | B31: 10 | C31: 안정제 | D31: 로커스트빈검 | E31: 0.05 | F31: 전분(가공) | G31: 1
A32: 과·채음료_딸기_11 | B32: 11 | C32: 안정제 | F32: 로커스트빈검 | G32: 0.175
A33: 과·채음료_딸기_12 | B33: 12 | C33: 안정제
A34: 과·채음료_딸기_13 | B34: 13 | C34: 기타 | D34: 구연산(무수) | E34: 0.2 | F34: 구연산(무수) | G34: 0.2
A35: 과·채음료_딸기_14 | B35: 14 | C35: 기타 | D35: 딸기향(수용성) | E35: 0.1 | F35: 딸기향(수용성) | G35: 0.5
A36: 과·채음료_딸기_15 | B36: 15 | C36: 기타 | D36: 아스코르빈산(비타민C) | E36: 0.05 | F36: 아스코르빈산(비타민C) | G36: 0.1
A37: 과·채음료_딸기_16 | B37: 16 | C37: 기타 | D37: 적색소(합성) | E37: 0.02 | F37: 적색소(합성) | G37: 0.1
A38: 과·채음료_딸기_17 | B38: 17 | C38: 기타 | D38: 구연산삼나트륨 | E38: 0.03 | F38: 구연산삼나트륨 | G38: 0.05
A39: 과·채음료_딸기_18 | B39: 18 | C39: 기타 | F39: 식이섬유 | G39: 0.5
A40: 과·채음료_딸기_19 | B40: 19 | C40: 기타 | F40: 혼합제제(폼크린200) | G40: 0.01
...
